Workbook

Sheet REKAP APAR FT MAOS
D1: Tanggal Service Exp Apar | K1: KETERANGAN APAR HARI | S1: UNIT EXP APAR | AB1: =TODAY() -> 46297
A2: NO | B2: NOPOL | C2: TRANSPORTIR | D2: CO2 PERTAMA | E2: CO2 KEDUA | F2: DCP PRESSURE 1 | G2: DCP PRESSURE 2 | H2: DCP CATRIDGE | I2: FOAM 1 | J2: FOAM 2 | K2: CO2 PERTAMA | L2: CO2 KEDUA | M2: DCP PRESSURE 1 | N2: DCP PRESSURE 2 | O2: FOAM 1 | P2: FOAM 2 | Q2: DCP CATRIDGE | S2: CO2 Pertama | T2: CO2 Kedua | U2: DCP 1 | V2: DCP 2 | W2: Foam 1 | X2: Foam 2 | Y2: Catride | Z2: Jumlah
A4: =A3+1 -> 1 | B4: AA8410OP | C4: PT RISKI HARTATA ABADI | D4: 46254 | E4: 46254 | H4: 46292 | J4: 46292 | K4: =IF(OR($AB$1="",D4=""),"",D4-$AB$1) -> -43 | L4: =IF(OR($AB$1="",E4=""),"",E4-$AB$1) -> -43 | M4: =IF(OR($AB$1="",F4=""),"",F4-$AB$1) | N4: =IF(OR($AB$1="",G4=""),"",G4-$AB$1) | O4: =IF(OR($AB$1="",I4=""),"",I4-$AB$1) | P4: =IF(OR($AB$1="",J4=""),"",J4-$AB$1) -> -5 | Q4: =IF(OR($AB$1="",J4=""),"",J4-$AB$1) -> -5 | S4: =COUNTIF(K4, "<30") -> 1 | T4: =COUNTIF(L4, "<30") -> 1 | U4: =COUNTIF(M4, "<30") -> 0 | X4: =COUNTIF(P4, "<30") -> 1 | Y4: =COUNTIF(Q4, "<30") -> 1 | Z4: =COUNTIF(S4:Y4, ">0") -> 4
A5: =A4+1 -> 2 | B5: AA8860OF | C5: PT RISKI HARTATA ABADI | D5: 46292 | E5: 46292 | F5: 46325 | J5: 46325 | K5: =IF(OR($AB$1="",D5=""),"",D5-$AB$1) -> -5 | L5: =IF(OR($AB$1="",E5=""),"",E5-$AB$1) -> -5 | M5: =IF(OR($AB$1="",F5=""),"",F5-$AB$1) -> 28 | N5: =IF(OR($AB$1="",G5=""),"",G5-$AB$1) | O5: =IF(OR($AB$1="",I5=""),"",I5-$AB$1) | P5: =IF(OR($AB$1="",J5=""),"",J5-$AB$1) -> 28 | Q5: =IF(OR($AB$1="",J5=""),"",J5-$AB$1) -> 28 | S5: =COUNTIF(K5, "<30") -> 1 | T5: =COUNTIF(L5, "<30") -> 1 | U5: =COUNTIF(M5, "<30") -> 1 | X5: =COUNTIF(P5, "<30") -> 1 | Y5: =COUNTIF(Q5, "<30") -> 1 | Z5: =COUNTIF(S5:Y5, ">0") -> 5
A6: =A5+1 -> 3 | B6: AD8603OH | C6: PT. KARYAMAS MANUNGGAL JAYA | F6: 46254 | G6: 46254 | I6: 46254 | J6: 46352 | K6: =IF(OR($AB$1="",D6=""),"",D6-$AB$1) | L6: =IF(OR($AB$1="",E6=""),"",E6-$AB$1) | M6: =IF(OR($AB$1="",F6=""),"",F6-$AB$1) -> -43 | N6: =IF(OR($AB$1="",G6=""),"",G6-$AB$1) -> -43 | O6: =IF(OR($AB$1="",I6=""),"",I6-$AB$1) -> -43 | P6: =IF(OR($AB$1="",J6=""),"",J6-$AB$1) -> 55 | Q6: =IF(OR($AB$1="",J6=""),"",J6-$AB$1) -> 55 | S6: =COUNTIF(K6, "<30") -> 0 | T6: =COUNTIF(L6, "<30") -> 0 | U6: =COUNTIF(M6, "<30") -> 1 | X6: =COUNTIF(P6, "<30") -> 0 | Y6: =COUNTIF(Q6, "<30") -> 0 | Z6: =COUNTIF(S6:Y6, ">0") -> 1
A7: =A6+1 -> 4 | B7: AD8618OH | C7: PT. KARYAMAS MANUNGGAL JAYA | F7: 46352 | G7: 46418 | I7: 46418 | J7: 46418 | K7: =IF(OR($AB$1="",D7=""),"",D7-$AB$1) | L7: =IF(OR($AB$1="",E7=""),"",E7-$AB$1) | M7: =IF(OR($AB$1="",F7=""),"",F7-$AB$1) -> 55 | N7: =IF(OR($AB$1="",G7=""),"",G7-$AB$1) -> 121 | O7: =IF(OR($AB$1="",I7=""),"",I7-$AB$1) -> 121 | P7: =IF(OR($AB$1="",J7=""),"",J7-$AB$1) -> 121 | Q7: =IF(OR($AB$1="",J7=""),"",J7-$AB$1) -> 121 | S7: =COUNTIF(K7, "<30") -> 0 | T7: =COUNTIF(L7, "<30") -> 0 | U7: =COUNTIF(M7, "<30") -> 0 | X7: =COUNTIF(P7, "<30") -> 0 | Y7: =COUNTIF(Q7, "<30") -> 0 | Z7: =COUNTIF(S7:Y7, ">0") -> 0
A8: =A7+1 -> 5 | B8: B9022SFV | C8: PT PERTAMINA PATRA NIAGA | D8: 46283 | E8: 46283 | H8: 46376 | J8: 46292 | K8: =IF(OR($AB$1="",D8=""),"",D8-$AB$1) -> -14 | L8: =IF(OR($AB$1="",E8=""),"",E8-$AB$1) -> -14 | M8: =IF(OR($AB$1="",F8=""),"",F8-$AB$1) | N8: =IF(OR($AB$1="",G8=""),"",G8-$AB$1) | O8: =IF(OR($AB$1="",I8=""),"",I8-$AB$1) | P8: =IF(OR($AB$1="",J8=""),"",J8-$AB$1) -> -5 | Q8: =IF(OR($AB$1="",J8=""),"",J8-$AB$1) -> -5 | S8: =COUNTIF(K8, "<30") -> 1 | T8: =COUNTIF(L8, "<30") -> 1 | U8: =COUNTIF(M8, "<30") -> 0 | X8: =COUNTIF(P8, "<30") -> 1 | Y8: =COUNTIF(Q8, "<30") -> 1 | Z8: =COUNTIF(S8:Y8, ">0") -> 4
A9: =A8+1 -> 6 | B9: B9061SFV | C9: PT. ELNUSA PETROFIN | D9: 46292 | E9: 46292 | H9: 46254 | J9: 46325 | K9: =IF(OR($AB$1="",D9=""),"",D9-$AB$1) -> -5 | L9: =IF(OR($AB$1="",E9=""),"",E9-$AB$1) -> -5 | M9: =IF(OR($AB$1="",F9=""),"",F9-$AB$1) | N9: =IF(OR($AB$1="",G9=""),"",G9-$AB$1) | O9: =IF(OR($AB$1="",I9=""),"",I9-$AB$1) | P9: =IF(OR($AB$1="",J9=""),"",J9-$AB$1) -> 28 | Q9: =IF(OR($AB$1="",J9=""),"",J9-$AB$1) -> 28 | S9: =COUNTIF(K9, "<30") -> 1 | T9: =COUNTIF(L9, "<30") -> 1 | U9: =COUNTIF(M9, "<30") -> 0 | X9: =COUNTIF(P9, "<30") -> 1 | Y9: =COUNTIF(Q9, "<30") -> 1 | Z9: =COUNTIF(S9:Y9, ">0") -> 4
A10: =A9+1 -> 7 | B10: B9077SEI | C10: PT PERTAMINA PATRA NIAGA | F10: 46292 | H10: 46292 | I10: 46292 | J10: 46292 | K10: =IF(OR($AB$1="",D10=""),"",D10-$AB$1) | L10: =IF(OR($AB$1="",E10=""),"",E10-$AB$1) | M10: =IF(OR($AB$1="",F10=""),"",F10-$AB$1) -> -5 | N10: =IF(OR($AB$1="",G10=""),"",G10-$AB$1) | O10: =IF(OR($AB$1="",I10=""),"",I10-$AB$1) -> -5 | P10: =IF(OR($AB$1="",J10=""),"",J10-$AB$1) -> -5 | Q10: =IF(OR($AB$1="",J10=""),"",J10-$AB$1) -> -5 | S10: =COUNTIF(K10, "<30") -> 0 | T10: =COUNTIF(L10, "<30") -> 0 | U10: =COUNTIF(M10, "<30") -> 1 | X10: =COUNTIF(P10, "<30") -> 1 | Y10: =COUNTIF(Q10, "<30") -> 1 | Z10: =COUNTIF(S10:Y10, ">0") -> 3
A11: =A10+1 -> 8 | B11: B9106SEI | C11: PT PERTAMINA PATRA NIAGA | F11: 46292 | G11: 46292 | I11: 46292 | J11: 46292 | K11: =IF(OR($AB$1="",D11=""),"",D11-$AB$1) | L11: =IF(OR($AB$1="",E11=""),"",E11-$AB$1) | M11: =IF(OR($AB$1="",F11=""),"",F11-$AB$1) -> -5 | N11: =IF(OR($AB$1="",G11=""),"",G11-$AB$1) -> -5 | O11: =IF(OR($AB$1="",I11=""),"",I11-$AB$1) -> -5 | P11: =IF(OR($AB$1="",J11=""),"",J11-$AB$1) -> -5 | Q11: =IF(OR($AB$1="",J11=""),"",J11-$AB$1) -> -5 | S11: =COUNTIF(K11, "<30") -> 0 | T11: =COUNTIF(L11, "<30") -> 0 | U11: =COUNTIF(M11, "<30") -> 1 | X11: =COUNTIF(P11, "<30") -> 1 | Y11: =COUNTIF(Q11, "<30") -> 1 | Z11: =COUNTIF(S11:Y11, ">0") -> 3
A12: =A11+1 -> 9 | B12: B9223SFV | C12: PT PERTAMINA PATRA NIAGA | D12: 46446 | E12: 46446 | H12: 46470 | J12: 46470 | K12: =IF(OR($AB$1="",D12=""),"",D12-$AB$1) -> 149 | L12: =IF(OR($AB$1="",E12=""),"",E12-$AB$1) -> 149 | M12: =IF(OR($AB$1="",F12=""),"",F12-$AB$1) | N12: =IF(OR($AB$1="",G12=""),"",G12-$AB$1) | O12: =IF(OR($AB$1="",I12=""),"",I12-$AB$1) | P12: =IF(OR($AB$1="",J12=""),"",J12-$AB$1) -> 173 | Q12: =IF(OR($AB$1="",J12=""),"",J12-$AB$1) -> 173 | S12: =COUNTIF(K12, "<30") -> 0 | T12: =COUNTIF(L12, "<30") -> 0 | U12: =COUNTIF(M12, "<30") -> 0 | X12: =COUNTIF(P12, "<30") -> 0 | Y12: =COUNTIF(Q12, "<30") -> 0 | Z12: =COUNTIF(S12:Y12, ">0") -> 0
A13: =A12+1 -> 10 | B13: B9290TFV | C13: PT. ADAM TRANS | D13: 46292 | E13: 46292 | H13: 46292 | J13: 46292 | K13: =IF(OR($AB$1="",D13=""),"",D13-$AB$1) -> -5 | L13: =IF(OR($AB$1="",E13=""),"",E13-$AB$1) -> -5 | M13: =IF(OR($AB$1="",F13=""),"",F13-$AB$1) | N13: =IF(OR($AB$1="",G13=""),"",G13-$AB$1) | O13: =IF(OR($AB$1="",I13=""),"",I13-$AB$1) | P13: =IF(OR($AB$1="",J13=""),"",J13-$AB$1) -> -5 | Q13: =IF(OR($AB$1="",J13=""),"",J13-$AB$1) -> -5 | S13: =COUNTIF(K13, "<30") -> 1 | T13: =COUNTIF(L13, "<30") -> 1 | U13: =COUNTIF(M13, "<30") -> 0 | X13: =COUNTIF(P13, "<30") -> 1 | Y13: =COUNTIF(Q13, "<30") -> 1 | Z13: =COUNTIF(S13:Y13, ">0") -> 4
A14: =A13+1 -> 11 | B14: B9300TFV | C14: PT. ADAM TRANS | D14: 46376 | E14: 46376 | H14: 46053 | J14: 46376 | K14: =IF(OR($AB$1="",D14=""),"",D14-$AB$1) -> 79 | L14: =IF(OR($AB$1="",E14=""),"",E14-$AB$1) -> 79 | M14: =IF(OR($AB$1="",F14=""),"",F14-$AB$1) | N14: =IF(OR($AB$1="",G14=""),"",G14-$AB$1) | O14: =IF(OR($AB$1="",I14=""),"",I14-$AB$1) | P14: =IF(OR($AB$1="",J14=""),"",J14-$AB$1) -> 79 | Q14: =IF(OR($AB$1="",J14=""),"",J14-$AB$1) -> 79 | S14: =COUNTIF(K14, "<30") -> 0 | T14: =COUNTIF(L14, "<30") -> 0 | U14: =COUNTIF(M14, "<30") -> 0 | X14: =COUNTIF(P14, "<30") -> 0 | Y14: =COUNTIF(Q14, "<30") -> 0 | Z14: =COUNTIF(S14:Y14, ">0") -> 0
A15: =A14+1 -> 12 | B15: B9355TFV | C15: PT. ADAM TRANS | D15: 46446 | E15: 46446 | H15: 46446 | J15: 46446 | K15: =IF(OR($AB$1="",D15=""),"",D15-$AB$1) -> 149 | L15: =IF(OR($AB$1="",E15=""),"",E15-$AB$1) -> 149 | M15: =IF(OR($AB$1="",F15=""),"",F15-$AB$1) | N15: =IF(OR($AB$1="",G15=""),"",G15-$AB$1) | O15: =IF(OR($AB$1="",I15=""),"",I15-$AB$1) | P15: =IF(OR($AB$1="",J15=""),"",J15-$AB$1) -> 149 | Q15: =IF(OR($AB$1="",J15=""),"",J15-$AB$1) -> 149 | S15: =COUNTIF(K15, "<30") -> 0 | T15: =COUNTIF(L15, "<30") -> 0 | U15: =COUNTIF(M15, "<30") -> 0 | X15: =COUNTIF(P15, "<30") -> 0 | Y15: =COUNTIF(Q15, "<30") -> 0 | Z15: =COUNTIF(S15:Y15, ">0") -> 0
A16: =A15+1 -> 13 | B16: B9376TFV | C16: PT. ADAM TRANS | D16: 46254 | E16: 46254 | F16: 46418 | J16: 46283 | K16: =IF(OR($AB$1="",D16=""),"",D16-$AB$1) -> -43 | L16: =IF(OR($AB$1="",E16=""),"",E16-$AB$1) -> -43 | M16: =IF(OR($AB$1="",F16=""),"",F16-$AB$1) -> 121 | N16: =IF(OR($AB$1="",G16=""),"",G16-$AB$1) | O16: =IF(OR($AB$1="",I16=""),"",I16-$AB$1) | P16: =IF(OR($AB$1="",J16=""),"",J16-$AB$1) -> -14 | Q16: =IF(OR($AB$1="",J16=""),"",J16-$AB$1) -> -14 | S16: =COUNTIF(K16, "<30") -> 1 | T16: =COUNTIF(L16, "<30") -> 1 | U16: =COUNTIF(M16, "<30") -> 0 | X16: =COUNTIF(P16, "<30") -> 1 | Y16: =COUNTIF(Q16, "<30") -> 1 | Z16: =COUNTIF(S16:Y16, ">0") -> 4
A17: =A16+1 -> 14 | B17: B9378TFV | C17: PT. ADAM TRANS | D17: 46292 | E17: 46292 | H17: 46254 | J17: 46292 | K17: 16 | L17: =IF(OR($AB$1="",E17=""),"",E17-$AB$1) -> -5 | M17: =IF(OR($AB$1="",F17=""),"",F17-$AB$1) | N17: =IF(OR($AB$1="",G17=""),"",G17-$AB$1) | O17: =IF(OR($AB$1="",I17=""),"",I17-$AB$1) | P17: =IF(OR($AB$1="",J17=""),"",J17-$AB$1) -> -5 | Q17: =IF(OR($AB$1="",J17=""),"",J17-$AB$1) -> -5 | S17: =COUNTIF(K17, "<30") -> 1 | T17: =COUNTIF(L17, "<30") -> 1 | U17: =COUNTIF(M17, "<30") -> 0 | X17: =COUNTIF(P17, "<30") -> 1 | Y17: =COUNTIF(Q17, "<30") -> 1 | Z17: =COUNTIF(S17:Y17, ">0") -> 4
A18: =A17+1 -> 15 | B18: B9504TEI | C18: PT. ADAM TRANS | D18: 46283 | H18: 46352 | J18: 46352 | K18: =IF(OR($AB$1="",D18=""),"",D18-$AB$1) -> -14 | L18: =IF(OR($AB$1="",E18=""),"",E18-$AB$1) | M18: =IF(OR($AB$1="",F18=""),"",F18-$AB$1) | N18: =IF(OR($AB$1="",G18=""),"",G18-$AB$1) | O18: =IF(OR($AB$1="",I18=""),"",I18-$AB$1) | P18: =IF(OR($AB$1="",J18=""),"",J18-$AB$1) -> 55 | Q18: =IF(OR($AB$1="",J18=""),"",J18-$AB$1) -> 55 | S18: =COUNTIF(K18, "<30") -> 1 | T18: =COUNTIF(L18, "<30") -> 0 | U18: =COUNTIF(M18, "<30") -> 0 | X18: =COUNTIF(P18, "<30") -> 0 | Y18: =COUNTIF(Q18, "<30") -> 0 | Z18: =COUNTIF(S18:Y18, ">0") -> 1
A19: =A18+1 -> 16 | B19: B9505TEI | C19: PT. ADAM TRANS | D19: 46446 | E19: 46446 | H19: 46446 | J19: 46292 | K19: =IF(OR($AB$1="",D19=""),"",D19-$AB$1) -> 149 | L19: =IF(OR($AB$1="",E19=""),"",E19-$AB$1) -> 149 | M19: =IF(OR($AB$1="",F19=""),"",F19-$AB$1) | N19: =IF(OR($AB$1="",G19=""),"",G19-$AB$1) | O19: =IF(OR($AB$1="",I19=""),"",I19-$AB$1) | P19: =IF(OR($AB$1="",J19=""),"",J19-$AB$1) -> -5 | Q19: =IF(OR($AB$1="",J19=""),"",J19-$AB$1) -> -5 | S19: =COUNTIF(K19, "<30") -> 0 | T19: =COUNTIF(L19, "<30") -> 0 | U19: =COUNTIF(M19, "<30") -> 0 | X19: =COUNTIF(P19, "<30") -> 1 | Y19: =COUNTIF(Q19, "<30") -> 1 | Z19: =COUNTIF(S19:Y19, ">0") -> 2
A20: =A19+1 -> 17 | B20: B9520TEI | C20: PT. ADAM TRANS | D20: 46283 | E20: 46283 | H20: 46446 | J20: 46446 | K20: =IF(OR($AB$1="",D20=""),"",D20-$AB$1) -> -14 | L20: =IF(OR($AB$1="",E20=""),"",E20-$AB$1) -> -14 | M20: =IF(OR($AB$1="",F20=""),"",F20-$AB$1) | N20: =IF(OR($AB$1="",G20=""),"",G20-$AB$1) | O20: =IF(OR($AB$1="",I20=""),"",I20-$AB$1) | P20: =IF(OR($AB$1="",J20=""),"",J20-$AB$1) -> 149 | Q20: =IF(OR($AB$1="",J20=""),"",J20-$AB$1) -> 149 | S20: =COUNTIF(K20, "<30") -> 1 | T20: =COUNTIF(L20, "<30") -> 1 | U20: =COUNTIF(M20, "<30") -> 0 | X20: =COUNTIF(P20, "<30") -> 0 | Y20: =COUNTIF(Q20, "<30") -> 0 | Z20: =COUNTIF(S20:Y20, ">0") -> 2
A21: =A20+1 -> 18 | B21: B9570SEI | C21: PT. ELNUSA PETROFIN | D21: 46446 | E21: 46446 | H21: 46352 | J21: 46352 | K21: =IF(OR($AB$1="",D21=""),"",D21-$AB$1) -> 149 | L21: =IF(OR($AB$1="",E21=""),"",E21-$AB$1) -> 149 | M21: =IF(OR($AB$1="",F21=""),"",F21-$AB$1) | N21: =IF(OR($AB$1="",G21=""),"",G21-$AB$1) | O21: =IF(OR($AB$1="",I21=""),"",I21-$AB$1) | P21: =IF(OR($AB$1="",J21=""),"",J21-$AB$1) -> 55 | Q21: =IF(OR($AB$1="",J21=""),"",J21-$AB$1) -> 55 | S21: =COUNTIF(K21, "<30") -> 0 | T21: =COUNTIF(L21, "<30") -> 0 | U21: =COUNTIF(M21, "<30") -> 0 | X21: =COUNTIF(P21, "<30") -> 0 | Y21: =COUNTIF(Q21, "<30") -> 0 | Z21: =COUNTIF(S21:Y21, ">0") -> 0
A22: =A21+1 -> 19 | B22: B9697SFV | C22: PT. ELNUSA PETROFIN | D22: 46446 | E22: 46446 | H22: 46325 | J22: 46283 | K22: =IF(OR($AB$1="",D22=""),"",D22-$AB$1) -> 149 | L22: =IF(OR($AB$1="",E22=""),"",E22-$AB$1) -> 149 | M22: =IF(OR($AB$1="",F22=""),"",F22-$AB$1) | N22: =IF(OR($AB$1="",G22=""),"",G22-$AB$1) | O22: =IF(OR($AB$1="",I22=""),"",I22-$AB$1) | P22: =IF(OR($AB$1="",J22=""),"",J22-$AB$1) -> -14 | Q22: =IF(OR($AB$1="",J22=""),"",J22-$AB$1) -> -14 | S22: =COUNTIF(K22, "<30") -> 0 | T22: =COUNTIF(L22, "<30") -> 0 | U22: =COUNTIF(M22, "<30") -> 0 | X22: =COUNTIF(P22, "<30") -> 1 | Y22: =COUNTIF(Q22, "<30") -> 1 | Z22: =COUNTIF(S22:Y22, ">0") -> 2
A23: =A22+1 -> 20 | B23: B9697SFV | C23: PT. ELNUSA PETROFIN | F23: 46376 | J23: 46376 | K23: =IF(OR($AB$1="",D23=""),"",D23-$AB$1) | L23: =IF(OR($AB$1="",E23=""),"",E23-$AB$1) | M23: =IF(OR($AB$1="",F23=""),"",F23-$AB$1) -> 79 | N23: =IF(OR($AB$1="",G23=""),"",G23-$AB$1) | O23: =IF(OR($AB$1="",I23=""),"",I23-$AB$1) | P23: =IF(OR($AB$1="",J23=""),"",J23-$AB$1) -> 79 | Q23: =IF(OR($AB$1="",J23=""),"",J23-$AB$1) -> 79 | S23: =COUNTIF(K23, "<30") -> 0 | T23: =COUNTIF(L23, "<30") -> 0 | U23: =COUNTIF(M23, "<30") -> 0 | X23: =COUNTIF(P23, "<30") -> 0 | Y23: =COUNTIF(Q23, "<30") -> 0 | Z23: =COUNTIF(S23:Y23, ">0") -> 0
A24: =A23+1 -> 21 | B24: B9570SEI | C24: PT. ELNUSA PETROFIN | F24: 46376 | J24: 46376 | K24: =IF(OR($AB$1="",D24=""),"",D24-$AB$1) | L24: =IF(OR($AB$1="",E24=""),"",E24-$AB$1) | M24: =IF(OR($AB$1="",F24=""),"",F24-$AB$1) -> 79 | N24: =IF(OR($AB$1="",G24=""),"",G24-$AB$1) | O24: =IF(OR($AB$1="",I24=""),"",I24-$AB$1) | P24: =IF(OR($AB$1="",J24=""),"",J24-$AB$1) -> 79 | Q24: =IF(OR($AB$1="",J24=""),"",J24-$AB$1) -> 79 | S24: =COUNTIF(K24, "<30") -> 0 | T24: =COUNTIF(L24, "<30") -> 0 | U24: =COUNTIF(M24, "<30") -> 0 | X24: =COUNTIF(P24, "<30") -> 0 | Y24: =COUNTIF(Q24, "<30") -> 0 | Z24: =COUNTIF(S24:Y24, ">0") -> 0
A25: =A24+1 -> 22 | B25: B9810TEI | C25: PT. ADAM TRANS | D25: 46418 | E25: 46418 | F25: 46376 | J25: 46254 | K25: =IF(OR($AB$1="",D25=""),"",D25-$AB$1) -> 121 | L25: =IF(OR($AB$1="",E25=""),"",E25-$AB$1) -> 121 | M25: =IF(OR($AB$1="",F25=""),"",F25-$AB$1) -> 79 | N25: =IF(OR($AB$1="",G25=""),"",G25-$AB$1) | O25: =IF(OR($AB$1="",I25=""),"",I25-$AB$1) | P25: =IF(OR($AB$1="",J25=""),"",J25-$AB$1) -> -43 | Q25: =IF(OR($AB$1="",J25=""),"",J25-$AB$1) -> -43 | S25: =COUNTIF(K25, "<30") -> 0 | T25: =COUNTIF(L25, "<30") -> 0 | U25: =COUNTIF(M25, "<30") -> 0 | X25: =COUNTIF(P25, "<30") -> 1 | Y25: =COUNTIF(Q25, "<30") -> 1 | Z25: =COUNTIF(S25:Y25, ">0") -> 2
A26: =A25+1 -> 23 | B26: B9811TEI | C26: PT. ADAM TRANS | D26: 46283 | E26: 46283 | H26: 46325 | J26: 46325 | K26: =IF(OR($AB$1="",D26=""),"",D26-$AB$1) -> -14 | L26: =IF(OR($AB$1="",E26=""),"",E26-$AB$1) -> -14 | M26: =IF(OR($AB$1="",F26=""),"",F26-$AB$1) | N26: =IF(OR($AB$1="",G26=""),"",G26-$AB$1) | O26: =IF(OR($AB$1="",I26=""),"",I26-$AB$1) | P26: =IF(OR($AB$1="",J26=""),"",J26-$AB$1) -> 28 | Q26: =IF(OR($AB$1="",J26=""),"",J26-$AB$1) -> 28 | S26: =COUNTIF(K26, "<30") -> 1 | T26: =COUNTIF(L26, "<30") -> 1 | U26: =COUNTIF(M26, "<30") -> 0 | X26: =COUNTIF(P26, "<30") -> 1 | Y26: =COUNTIF(Q26, "<30") -> 1 | Z26: =COUNTIF(S26:Y26, ">0") -> 4
A27: =A26+1 -> 24 | B27: B9812TEI | C27: PT. ADAM TRANS | D27: 46283 | E27: 46283 | H27: 46254 | J27: 46254 | K27: =IF(OR($AB$1="",D27=""),"",D27-$AB$1) -> -14 | L27: =IF(OR($AB$1="",E27=""),"",E27-$AB$1) -> -14 | M27: =IF(OR($AB$1="",F27=""),"",F27-$AB$1) | N27: =IF(OR($AB$1="",G27=""),"",G27-$AB$1) | O27: =IF(OR($AB$1="",I27=""),"",I27-$AB$1) | P27: =IF(OR($AB$1="",J27=""),"",J27-$AB$1) -> -43 | Q27: =IF(OR($AB$1="",J27=""),"",J27-$AB$1) -> -43 | S27: =COUNTIF(K27, "<30") -> 1 | T27: =COUNTIF(L27, "<30") -> 1 | U27: =COUNTIF(M27, "<30") -> 0 | X27: =COUNTIF(P27, "<30") -> 1 | Y27: =COUNTIF(Q27, "<30") -> 1 | Z27: =COUNTIF(S27:Y27, ">0") -> 4
A28: =A27+1 -> 25 | B28: E9225YC | C28: PT.PUSPITA CIPTA | D28: 46283 | E28: 46283 | H28: 46283 | J28: 46283 | K28: =IF(OR($AB$1="",D28=""),"",D28-$AB$1) -> -14 | L28: =IF(OR($AB$1="",E28=""),"",E28-$AB$1) -> -14 | M28: =IF(OR($AB$1="",F28=""),"",F28-$AB$1) | N28: =IF(OR($AB$1="",G28=""),"",G28-$AB$1) | O28: =IF(OR($AB$1="",I28=""),"",I28-$AB$1) | P28: =IF(OR($AB$1="",J28=""),"",J28-$AB$1) -> -14 | Q28: =IF(OR($AB$1="",J28=""),"",J28-$AB$1) -> -14 | S28: =COUNTIF(K28, "<30") -> 1 | T28: =COUNTIF(L28, "<30") -> 1 | U28: =COUNTIF(M28, "<30") -> 0 | X28: =COUNTIF(P28, "<30") -> 1 | Y28: =COUNTIF(Q28, "<30") -> 1 | Z28: =COUNTIF(S28:Y28, ">0") -> 4
A29: =A28+1 -> 26 | B29: E9264YC | C29: PT.PUSPITA CIPTA | D29: 46254 | E29: 46254 | H29: 46376 | J29: 46254 | K29: =IF(OR($AB$1="",D29=""),"",D29-$AB$1) -> -43 | L29: =IF(OR($AB$1="",E29=""),"",E29-$AB$1) -> -43 | M29: =IF(OR($AB$1="",F29=""),"",F29-$AB$1) | N29: =IF(OR($AB$1="",G29=""),"",G29-$AB$1) | O29: =IF(OR($AB$1="",I29=""),"",I29-$AB$1) | P29: =IF(OR($AB$1="",J29=""),"",J29-$AB$1) -> -43 | Q29: =IF(OR($AB$1="",J29=""),"",J29-$AB$1) -> -43 | S29: =COUNTIF(K29, "<30") -> 1 | T29: =COUNTIF(L29, "<30") -> 1 | U29: =COUNTIF(M29, "<30") -> 0 | V29: =COUNTIF(N29, "<30") -> 0 | W29: =COUNTIF(O29, "<30") -> 0 | X29: =COUNTIF(P29, "<30") -> 1 | Y29: =COUNTIF(Q29, "<30") -> 1 | Z29: =COUNTIF(S29:Y29, ">0") -> 4
A30: =A29+1 -> 27 | B30: E9334YC | C30: PT.PUSPITA CIPTA | D30: 45890 | E30: 45890 | H30: 46254 | J30: 46352 | K30: =IF(OR($AB$1="",D30=""),"",D30-$AB$1) -> -407 | L30: =IF(OR($AB$1="",E30=""),"",E30-$AB$1) -> -407 | M30: =IF(OR($AB$1="",F30=""),"",F30-$AB$1) | N30: =IF(OR($AB$1="",G30=""),"",G30-$AB$1) | O30: =IF(OR($AB$1="",I30=""),"",I30-$AB$1) | P30: =IF(OR($AB$1="",J30=""),"",J30-$AB$1) -> 55 | Q30: =IF(OR($AB$1="",J30=""),"",J30-$AB$1) -> 55 | S30: =COUNTIF(K30, "<30") -> 1 | T30: =COUNTIF(L30, "<30") -> 1 | U30: =COUNTIF(M30, "<30") -> 0 | V30: =COUNTIF(N30, "<30") -> 0 | W30: =COUNTIF(O30, "<30") -> 0 | X30: =COUNTIF(P30, "<30") -> 0 | Y30: =COUNTIF(Q30, "<30") -> 0 | Z30: =COUNTIF(S30:Y30, ">0") -> 2
A31: =A30+1 -> 28 | B31: E9335YC | C31: PT.PUSPITA CIPTA | D31: 46254 | E31: 46254 | H31: 46325 | J31: 46283 | K31: =IF(OR($AB$1="",D31=""),"",D31-$AB$1) -> -43 | L31: =IF(OR($AB$1="",E31=""),"",E31-$AB$1) -> -43 | M31: =IF(OR($AB$1="",F31=""),"",F31-$AB$1) | N31: =IF(OR($AB$1="",G31=""),"",G31-$AB$1) | O31: =IF(OR($AB$1="",I31=""),"",I31-$AB$1) | P31: =IF(OR($AB$1="",J31=""),"",J31-$AB$1) -> -14 | Q31: =IF(OR($AB$1="",J31=""),"",J31-$AB$1) -> -14 | S31: =COUNTIF(K31, "<30") -> 1 | T31: =COUNTIF(L31, "<30") -> 1 | U31: =COUNTIF(M31, "<30") -> 0 | V31: =COUNTIF(N31, "<30") -> 0 | W31: =COUNTIF(O31, "<30") -> 0 | X31: =COUNTIF(P31, "<30") -> 1 | Y31: =COUNTIF(Q31, "<30") -> 1 | Z31: =COUNTIF(S31:Y31, ">0") -> 4
A32: =A31+1 -> 29 | B32: E9412YC | C32: PT.PUSPITA CIPTA | D32: 46283 | E32: 46283 | H32: 46446 | J32: 46352 | K32: =IF(OR($AB$1="",D32=""),"",D32-$AB$1) -> -14 | L32: =IF(OR($AB$1="",E32=""),"",E32-$AB$1) -> -14 | M32: =IF(OR($AB$1="",F32=""),"",F32-$AB$1) | N32: =IF(OR($AB$1="",G32=""),"",G32-$AB$1) | O32: =IF(OR($AB$1="",I32=""),"",I32-$AB$1) | P32: =IF(OR($AB$1="",J32=""),"",J32-$AB$1) -> 55 | Q32: =IF(OR($AB$1="",J32=""),"",J32-$AB$1) -> 55 | S32: =COUNTIF(K32, "<30") -> 1 | T32: =COUNTIF(L32, "<30") -> 1 | U32: =COUNTIF(M32, "<30") -> 0 | V32: =COUNTIF(N32, "<30") -> 0 | W32: =COUNTIF(O32, "<30") -> 0 | X32: =COUNTIF(P32, "<30") -> 0 | Y32: =COUNTIF(Q32, "<30") -> 0 | Z32: =COUNTIF(S32:Y32, ">0") -> 2
A33: =A32+1 -> 30 | B33: E9445YC | C33: PT.PUSPITA CIPTA | D33: 46418 | E33: 46418 | H33: 46352 | J33: 46352 | K33: =IF(OR($AB$1="",D33=""),"",D33-$AB$1) -> 121 | L33: =IF(OR($AB$1="",E33=""),"",E33-$AB$1) -> 121 | M33: =IF(OR($AB$1="",F33=""),"",F33-$AB$1) | N33: =IF(OR($AB$1="",G33=""),"",G33-$AB$1) | O33: =IF(OR($AB$1="",I33=""),"",I33-$AB$1) | P33: =IF(OR($AB$1="",J33=""),"",J33-$AB$1) -> 55 | Q33: =IF(OR($AB$1="",J33=""),"",J33-$AB$1) -> 55 | S33: =COUNTIF(K33, "<30") -> 0 | T33: =COUNTIF(L33, "<30") -> 0 | U33: =COUNTIF(M33, "<30") -> 0 | V33: =COUNTIF(N33, "<30") -> 0 | W33: =COUNTIF(O33, "<30") -> 0 | X33: =COUNTIF(P33, "<30") -> 0 | Y33: =COUNTIF(Q33, "<30") -> 0 | Z33: =COUNTIF(S33:Y33, ">0") -> 0
A34: =A33+1 -> 31 | B34: E9450YC | C34: PT.PUSPITA CIPTA | D34: 46254 | E34: 46254 | H34: 46446 | J34: 46053 | K34: =IF(OR($AB$1="",D34=""),"",D34-$AB$1) -> -43 | L34: =IF(OR($AB$1="",E34=""),"",E34-$AB$1) -> -43 | M34: =IF(OR($AB$1="",F34=""),"",F34-$AB$1) | N34: =IF(OR($AB$1="",G34=""),"",G34-$AB$1) | O34: =IF(OR($AB$1="",I34=""),"",I34-$AB$1) | P34: =IF(OR($AB$1="",J34=""),"",J34-$AB$1) -> -244 | Q34: =IF(OR($AB$1="",J34=""),"",J34-$AB$1) -> -244 | S34: =COUNTIF(K34, "<30") -> 1 | T34: =COUNTIF(L34, "<30") -> 1 | U34: =COUNTIF(M34, "<30") -> 0 | V34: =COUNTIF(N34, "<30") -> 0 | W34: =COUNTIF(O34, "<30") -> 0 | X34: =COUNTIF(P34, "<30") -> 1 | Y34: =COUNTIF(Q34, "<30") -> 1 | Z34: =COUNTIF(S34:Y34, ">0") -> 4
A35: =A34+1 -> 32 | B35: E9542YC | C35: PT.PUSPITA CIPTA | D35: 46229 | E35: 46229 | H35: 46325 | J35: 46418 | K35: =IF(OR($AB$1="",D35=""),"",D35-$AB$1) -> -68 | L35: =IF(OR($AB$1="",E35=""),"",E35-$AB$1) -> -68 | M35: =IF(OR($AB$1="",F35=""),"",F35-$AB$1) | N35: =IF(OR($AB$1="",G35=""),"",G35-$AB$1) | O35: =IF(OR($AB$1="",I35=""),"",I35-$AB$1) | P35: =IF(OR($AB$1="",J35=""),"",J35-$AB$1) -> 121 | Q35: =IF(OR($AB$1="",J35=""),"",J35-$AB$1) -> 121 | S35: =COUNTIF(K35, "<30") -> 1 | T35: =COUNTIF(L35, "<30") -> 1 | U35: =COUNTIF(M35, "<30") -> 0 | V35: =COUNTIF(N35, "<30") -> 0 | W35: =COUNTIF(O35, "<30") -> 0 | X35: =COUNTIF(P35, "<30") -> 0 | Y35: =COUNTIF(Q35, "<30") -> 0 | Z35: =COUNTIF(S35:Y35, ">0") -> 2
A36: =A35+1 -> 33 | B36: E9453YC | C36: PT.PUSPITA CIPTA | D36: 46283 | E36: 46283 | H36: 46283 | J36: 46283 | K36: =IF(OR($AB$1="",D36=""),"",D36-$AB$1) -> -14 | L36: =IF(OR($AB$1="",E36=""),"",E36-$AB$1) -> -14 | M36: =IF(OR($AB$1="",F36=""),"",F36-$AB$1) | N36: =IF(OR($AB$1="",G36=""),"",G36-$AB$1) | O36: =IF(OR($AB$1="",I36=""),"",I36-$AB$1) | P36: =IF(OR($AB$1="",J36=""),"",J36-$AB$1) -> -14 | Q36: =IF(OR($AB$1="",J36=""),"",J36-$AB$1) -> -14 | S36: =COUNTIF(K36, "<30") -> 1 | T36: =COUNTIF(L36, "<30") -> 1 | U36: =COUNTIF(M36, "<30") -> 0 | V36: =COUNTIF(N36, "<30") -> 0 | W36: =COUNTIF(O36, "<30") -> 0 | X36: =COUNTIF(P36, "<30") -> 1 | Y36: =COUNTIF(Q36, "<30") -> 1 | Z36: =COUNTIF(S36:Y36, ">0") -> 4
A37: =A36+1 -> 34 | B37: E9493YC | C37: PT.PUSPITA CIPTA | D37: 46283 | E37: 46283 | H37: 46292 | J37: 46352 | K37: =IF(OR($AB$1="",D37=""),"",D37-$AB$1) -> -14 | L37: =IF(OR($AB$1="",E37=""),"",E37-$AB$1) -> -14 | M37: =IF(OR($AB$1="",F37=""),"",F37-$AB$1) | N37: =IF(OR($AB$1="",G37=""),"",G37-$AB$1) | O37: =IF(OR($AB$1="",I37=""),"",I37-$AB$1) | P37: =IF(OR($AB$1="",J37=""),"",J37-$AB$1) -> 55 | Q37: =IF(OR($AB$1="",J37=""),"",J37-$AB$1) -> 55 | S37: =COUNTIF(K37, "<30") -> 1 | T37: =COUNTIF(L37, "<30") -> 1 | U37: =COUNTIF(M37, "<30") -> 0 | V37: =COUNTIF(N37, "<30") -> 0 | W37: =COUNTIF(O37, "<30") -> 0 | X37: =COUNTIF(P37, "<30") -> 0 | Y37: =COUNTIF(Q37, "<30") -> 0 | Z37: =COUNTIF(S37:Y37, ">0") -> 2
A38: =A37+1 -> 35 | B38: E9495YC | C38: PT.PUSPITA CIPTA | D38: 46292 | E38: 46292 | H38: 46325 | J38: 46325 | K38: =IF(OR($AB$1="",D38=""),"",D38-$AB$1) -> -5 | L38: =IF(OR($AB$1="",E38=""),"",E38-$AB$1) -> -5 | M38: =IF(OR($AB$1="",F38=""),"",F38-$AB$1) | N38: =IF(OR($AB$1="",G38=""),"",G38-$AB$1) | O38: =IF(OR($AB$1="",I38=""),"",I38-$AB$1) | P38: =IF(OR($AB$1="",J38=""),"",J38-$AB$1) -> 28 | Q38: =IF(OR($AB$1="",J38=""),"",J38-$AB$1) -> 28 | S38: =COUNTIF(K38, "<30") -> 1 | T38: =COUNTIF(L38, "<30") -> 1 | U38: =COUNTIF(M38, "<30") -> 0 | V38: =COUNTIF(N38, "<30") -> 0 | W38: =COUNTIF(O38, "<30") -> 0 | X38: =COUNTIF(P38, "<30") -> 1 | Y38: =COUNTIF(Q38, "<30") -> 1 | Z38: =COUNTIF(S38:Y38, ">0") -> 4
A39: =A38+1 -> 36 | B39: E9496YC | C39: PT.PUSPITA CIPTA | D39: 46292 | E39: 46292 | H39: 46292 | J39: 46376 | K39: =IF(OR($AB$1="",D39=""),"",D39-$AB$1) -> -5 | L39: =IF(OR($AB$1="",E39=""),"",E39-$AB$1) -> -5 | M39: =IF(OR($AB$1="",F39=""),"",F39-$AB$1) | N39: =IF(OR($AB$1="",G39=""),"",G39-$AB$1) | O39: =IF(OR($AB$1="",I39=""),"",I39-$AB$1) | P39: =IF(OR($AB$1="",J39=""),"",J39-$AB$1) -> 79 | Q39: =IF(OR($AB$1="",J39=""),"",J39-$AB$1) -> 79 | S39: =COUNTIF(K39, "<30") -> 1 | T39: =COUNTIF(L39, "<30") -> 1 | U39: =COUNTIF(M39, "<30") -> 0 | V39: =COUNTIF(N39, "<30") -> 0 | W39: =COUNTIF(O39, "<30") -> 0 | X39: =COUNTIF(P39, "<30") -> 0 | Y39: =COUNTIF(Q39, "<30") -> 0 | Z39: =COUNTIF(S39:Y39, ">0") -> 2
A40: =A39+1 -> 37 | B40: E9512YC | C40: PT.PUSPITA CIPTA | D40: 46446 | E40: 46446 | H40: 46292 | J40: 46325 | K40: =IF(OR($AB$1="",D40=""),"",D40-$AB$1) -> 149 | L40: =IF(OR($AB$1="",E40=""),"",E40-$AB$1) -> 149 | M40: =IF(OR($AB$1="",F40=""),"",F40-$AB$1) | N40: =IF(OR($AB$1="",G40=""),"",G40-$AB$1) | O40: =IF(OR($AB$1="",I40=""),"",I40-$AB$1) | P40: =IF(OR($AB$1="",J40=""),"",J40-$AB$1) -> 28 | Q40: =IF(OR($AB$1="",J40=""),"",J40-$AB$1) -> 28 | S40: =COUNTIF(K40, "<30") -> 0 | T40: =COUNTIF(L40, "<30") -> 0 | U40: =COUNTIF(M40, "<30") -> 0 | V40: =COUNTIF(N40, "<30") -> 0 | W40: =COUNTIF(O40, "<30") -> 0 | X40: =COUNTIF(P40, "<30") -> 1 | Y40: =COUNTIF(Q40, "<30") -> 1 | Z40: =COUNTIF(S40:Y40, ">0") -> 2
A41: =A40+1 -> 38 | B41: E9535YC | C41: PT.PUSPITA CIPTA | D41: 46292 | E41: 46292 | H41: 46446 | J41: 46446 | K41: =IF(OR($AB$1="",D41=""),"",D41-$AB$1) -> -5 | L41: =IF(OR($AB$1="",E41=""),"",E41-$AB$1) -> -5 | M41: =IF(OR($AB$1="",F41=""),"",F41-$AB$1) | N41: =IF(OR($AB$1="",G41=""),"",G41-$AB$1) | O41: =IF(OR($AB$1="",I41=""),"",I41-$AB$1) | P41: =IF(OR($AB$1="",J41=""),"",J41-$AB$1) -> 149 | Q41: =IF(OR($AB$1="",J41=""),"",J41-$AB$1) -> 149 | S41: =COUNTIF(K41, "<30") -> 1 | T41: =COUNTIF(L41, "<30") -> 1 | U41: =COUNTIF(M41, "<30") -> 0 | V41: =COUNTIF(N41, "<30") -> 0 | W41: =COUNTIF(O41, "<30") -> 0 | X41: =COUNTIF(P41, "<30") -> 0 | Y41: =COUNTIF(Q41, "<30") -> 0 | Z41: =COUNTIF(S41:Y41, ">0") -> 2
...

Sheet Sheet8
A1: =#REF!+1 -> #REF! | B1: B9800SFU | C1: PT PERTAMINA PATRA NIAGA | D1: 46229 | E1: 46229 | I1: 46283 | J1: 46283 | K1: =IF(OR($AB$1="",E1=""),"",E1-$AB$1) | L1: =IF(OR($AB$1="",E1=""),"",E1-$AB$1) | M1: =IF(OR($AB$1="",F1=""),"",F1-$AB$1) | N1: =IF(OR($AB$1="",G1=""),"",G1-$AB$1) | O1: =IF(OR($AB$1="",H1=""),"",H1-$AB$1) | P1: =IF(OR($AB$1="",I1=""),"",I1-$AB$1) | Q1: =IF(OR($AB$1="",J1=""),"",J1-$AB$1) | S1: =COUNTIF(K1, "<30") -> 0 | T1: =COUNTIF(L1, "<30") -> 0 | U1: =COUNTIF(M1, "<30") -> 0 | X1: =COUNTIF(P1, "<30") -> 0 | Y1: =COUNTIF(Q1, "<30") -> 0 | Z1: =COUNTIF(S1:Y1, ">0") -> 0
A2: =A1+1 -> #REF! | B2: B9805SFU | C2: PT PERTAMINA PATRA NIAGA | D2: 46283 | E2: 46283 | I2: 46292 | J2: 46292 | K2: =IF(OR($AB$1="",D2=""),"",D2-$AB$1) | L2: =IF(OR($AB$1="",E2=""),"",E2-$AB$1) | M2: =IF(OR($AB$1="",F2=""),"",F2-$AB$1) | N2: =IF(OR($AB$1="",G2=""),"",G2-$AB$1) | O2: =IF(OR($AB$1="",H2=""),"",H2-$AB$1) | P2: =IF(OR($AB$1="",I2=""),"",I2-$AB$1) | Q2: =IF(OR($AB$1="",J2=""),"",J2-$AB$1) | S2: =COUNTIF(K2, "<30") -> 0 | T2: =COUNTIF(L2, "<30") -> 0 | U2: =COUNTIF(M2, "<30") -> 0 | X2: =COUNTIF(P2, "<30") -> 0 | Y2: =COUNTIF(Q2, "<30") -> 0 | Z2: =COUNTIF(S2:Y2, ">0") -> 0

Sheet REKAP APAR IT CILACAP
D1: Tanggal Service Exp Apar | L1: KETERANGAN APAR HARI | U1: UNIT EXP APAR | AD1: =TODAY() -> 46297
A2: NO | B2: NOPOL | C2: TRANSPORTIR | D2: CO2 Pertama | E2: CO2 Kedua | F2: DCP PRESSURE | G2: DCP PRESSURE | H2: FOAM | I2: FOAM | J2: DCP CATRIDGE | K2: DCP CATRIDGE | L2: CO2 Pertama | M2: CO2 Kedua | N2: DCP | O2: DCP | P2: Foam | Q2: Foam | R2: Catride | S2: Catride | U2: CO2 Pertama | V2: CO2 Kedua | W2: DCP | X2: DCP | Y2: Foam | Z2: Catride | AA2: Catride | AB2: Jumlah
A4: 1 | B4: D9524AG | C4: PT. LOGISTIK ENERGY ARMADA PRIMA | H4: 46259 | I4: 46259 | J4: 46259 | K4: 46259 | L4: =IF(OR($AD$1="",D4=""),"",D4-$AD$1) | M4: =IF(OR($AD$1="",E4=""),"",E4-$AD$1) | N4: =IF(OR($AD$1="",F4=""),"",F4-$AD$1) | O4: =IF(OR($AD$1="",G4=""),"",G4-$AD$1) | P4: =IF(OR($AD$1="",H4=""),"",H4-$AD$1) -> -38 | Q4: =IF(OR($AD$1="",I4=""),"",I4-$AD$1) -> -38 | R4: =IF(OR($AD$1="",J4=""),"",J4-$AD$1) -> -38 | S4: =IF(OR($AD$1="",K4=""),"",K4-$AD$1) -> -38 | U4: =COUNTIF(L4, "<30") -> 0 | V4: =COUNTIF(M4, "<30") -> 0 | W4: =COUNTIF(N4, "<30") -> 0 | X4: =COUNTIF(O4, "<30") -> 0 | Y4: =COUNTIF(Q4, "<30") -> 1 | Z4: =COUNTIF(R4, "<30") -> 1 | AA4: =COUNTIF(S4, "<30") -> 1 | AB4: =COUNTIF(U4:AA4, ">0") -> 3
A5: =A4+1 -> 2 | B5: D9527AG | C5: PT. LOGISTIK ENERGY ARMADA PRIMA | H5: 46259 | I5: 46259 | J5: 46259 | K5: 46259 | L5: =IF(OR($AD$1="",D5=""),"",D5-$AD$1) | M5: =IF(OR($AD$1="",E5=""),"",E5-$AD$1) | N5: =IF(OR($AD$1="",F5=""),"",F5-$AD$1) | O5: =IF(OR($AD$1="",G5=""),"",G5-$AD$1) | P5: =IF(OR($AD$1="",H5=""),"",H5-$AD$1) -> -38 | Q5: =IF(OR($AD$1="",I5=""),"",I5-$AD$1) -> -38 | R5: =IF(OR($AD$1="",J5=""),"",J5-$AD$1) -> -38 | S5: =IF(OR($AD$1="",K5=""),"",K5-$AD$1) -> -38 | U5: =COUNTIF(L5, "<30") -> 0 | V5: =COUNTIF(M5, "<30") -> 0 | W5: =COUNTIF(N5, "<30") -> 0 | X5: =COUNTIF(O5, "<30") -> 0 | Y5: =COUNTIF(Q5, "<30") -> 1 | Z5: =COUNTIF(R5, "<30") -> 1 | AA5: =COUNTIF(S5, "<30") -> 1 | AB5: =COUNTIF(U5:AA5, ">0") -> 3
A6: =A5+1 -> 3 | B6: B9870SEI | C6: PT. TRANSMIGASINDO | F6: 46259 | G6: 46259 | H6: 46259 | I6: 46259 | L6: =IF(OR($AD$1="",D6=""),"",D6-$AD$1) | M6: =IF(OR($AD$1="",E6=""),"",E6-$AD$1) | N6: =IF(OR($AD$1="",F6=""),"",F6-$AD$1) -> -38 | O6: =IF(OR($AD$1="",G6=""),"",G6-$AD$1) -> -38 | P6: =IF(OR($AD$1="",H6=""),"",H6-$AD$1) -> -38 | Q6: =IF(OR($AD$1="",I6=""),"",I6-$AD$1) -> -38 | R6: =IF(OR($AD$1="",J6=""),"",J6-$AD$1) | S6: =IF(OR($AD$1="",K6=""),"",K6-$AD$1) | U6: =COUNTIF(L6, "<30") -> 0 | V6: =COUNTIF(M6, "<30") -> 0 | W6: =COUNTIF(N6, "<30") -> 1 | X6: =COUNTIF(O6, "<30") -> 1 | Y6: =COUNTIF(Q6, "<30") -> 1 | Z6: =COUNTIF(R6, "<30") -> 0 | AA6: =COUNTIF(S6, "<30") -> 0 | AB6: =COUNTIF(U6:AA6, ">0") -> 3
A7: =A6+1 -> 4 | B7: B9868SEI | C7: PT. TRANSMIGASINDO | F7: 46259 | G7: 46259 | H7: 46259 | I7: 46259 | L7: =IF(OR($AD$1="",D7=""),"",D7-$AD$1) | M7: =IF(OR($AD$1="",E7=""),"",E7-$AD$1) | N7: =IF(OR($AD$1="",F7=""),"",F7-$AD$1) -> -38 | O7: =IF(OR($AD$1="",G7=""),"",G7-$AD$1) -> -38 | P7: =IF(OR($AD$1="",H7=""),"",H7-$AD$1) -> -38 | Q7: =IF(OR($AD$1="",I7=""),"",I7-$AD$1) -> -38 | R7: =IF(OR($AD$1="",J7=""),"",J7-$AD$1) | S7: =IF(OR($AD$1="",K7=""),"",K7-$AD$1) | U7: =COUNTIF(L7, "<30") -> 0 | V7: =COUNTIF(M7, "<30") -> 0 | W7: =COUNTIF(N7, "<30") -> 1 | X7: =COUNTIF(O7, "<30") -> 1 | Y7: =COUNTIF(Q7, "<30") -> 1 | Z7: =COUNTIF(R7, "<30") -> 0 | AA7: =COUNTIF(S7, "<30") -> 0 | AB7: =COUNTIF(U7:AA7, ">0") -> 3
A8: =A7+1 -> 5 | B8: B9875SEI | C8: PT. TRANSMIGASINDO | F8: 46259 | G8: 46259 | H8: 46259 | I8: 46259 | L8: =IF(OR($AD$1="",D8=""),"",D8-$AD$1) | M8: =IF(OR($AD$1="",E8=""),"",E8-$AD$1) | N8: =IF(OR($AD$1="",F8=""),"",F8-$AD$1) -> -38 | O8: =IF(OR($AD$1="",G8=""),"",G8-$AD$1) -> -38 | P8: =IF(OR($AD$1="",H8=""),"",H8-$AD$1) -> -38 | Q8: =IF(OR($AD$1="",I8=""),"",I8-$AD$1) -> -38 | R8: =IF(OR($AD$1="",J8=""),"",J8-$AD$1) | S8: =IF(OR($AD$1="",K8=""),"",K8-$AD$1) | U8: =COUNTIF(L8, "<30") -> 0 | V8: =COUNTIF(M8, "<30") -> 0 | W8: =COUNTIF(N8, "<30") -> 1 | X8: =COUNTIF(O8, "<30") -> 1 | Y8: =COUNTIF(Q8, "<30") -> 1 | Z8: =COUNTIF(R8, "<30") -> 0 | AA8: =COUNTIF(S8, "<30") -> 0 | AB8: =COUNTIF(U8:AA8, ">0") -> 3
A9: =A8+1 -> 6 | B9: B9873SEI | C9: PT. TRANSMIGASINDO | F9: 46259 | G9: 46259 | H9: 46259 | I9: 46259 | L9: =IF(OR($AD$1="",D9=""),"",D9-$AD$1) | M9: =IF(OR($AD$1="",E9=""),"",E9-$AD$1) | N9: =IF(OR($AD$1="",F9=""),"",F9-$AD$1) -> -38 | O9: =IF(OR($AD$1="",G9=""),"",G9-$AD$1) -> -38 | P9: =IF(OR($AD$1="",H9=""),"",H9-$AD$1) -> -38 | Q9: =IF(OR($AD$1="",I9=""),"",I9-$AD$1) -> -38 | R9: =IF(OR($AD$1="",J9=""),"",J9-$AD$1) | S9: =IF(OR($AD$1="",K9=""),"",K9-$AD$1) | U9: =COUNTIF(L9, "<30") -> 0 | V9: =COUNTIF(M9, "<30") -> 0 | W9: =COUNTIF(N9, "<30") -> 1 | X9: =COUNTIF(O9, "<30") -> 1 | Y9: =COUNTIF(Q9, "<30") -> 1 | Z9: =COUNTIF(R9, "<30") -> 0 | AA9: =COUNTIF(S9, "<30") -> 0 | AB9: =COUNTIF(U9:AA9, ">0") -> 3
A10: =A9+1 -> 7 | B10: B9869SEI | C10: PT. TRANSMIGASINDO | F10: 46259 | G10: 46259 | H10: 46259 | I10: 46259 | L10: =IF(OR($AD$1="",D10=""),"",D10-$AD$1) | M10: =IF(OR($AD$1="",E10=""),"",E10-$AD$1) | N10: =IF(OR($AD$1="",F10=""),"",F10-$AD$1) -> -38 | O10: =IF(OR($AD$1="",G10=""),"",G10-$AD$1) -> -38 | P10: =IF(OR($AD$1="",H10=""),"",H10-$AD$1) -> -38 | Q10: =IF(OR($AD$1="",I10=""),"",I10-$AD$1) -> -38 | R10: =IF(OR($AD$1="",J10=""),"",J10-$AD$1) | S10: =IF(OR($AD$1="",K10=""),"",K10-$AD$1) | U10: =COUNTIF(L10, "<30") -> 0 | V10: =COUNTIF(M10, "<30") -> 0 | W10: =COUNTIF(N10, "<30") -> 1 | X10: =COUNTIF(O10, "<30") -> 1 | Y10: =COUNTIF(Q10, "<30") -> 1 | Z10: =COUNTIF(R10, "<30") -> 0 | AA10: =COUNTIF(S10, "<30") -> 0 | AB10: =COUNTIF(U10:AA10, ">0") -> 3
A11: =A10+1 -> 8 | B11: B9867SEI | C11: PT. TRANSMIGASINDO | F11: 46259 | G11: 46259 | H11: 46259 | I11: 46259 | L11: =IF(OR($AD$1="",D11=""),"",D11-$AD$1) | M11: =IF(OR($AD$1="",E11=""),"",E11-$AD$1) | N11: =IF(OR($AD$1="",F11=""),"",F11-$AD$1) -> -38 | O11: =IF(OR($AD$1="",G11=""),"",G11-$AD$1) -> -38 | P11: =IF(OR($AD$1="",H11=""),"",H11-$AD$1) -> -38 | Q11: =IF(OR($AD$1="",I11=""),"",I11-$AD$1) -> -38 | R11: =IF(OR($AD$1="",J11=""),"",J11-$AD$1) | S11: =IF(OR($AD$1="",K11=""),"",K11-$AD$1) | U11: =COUNTIF(L11, "<30") -> 0 | V11: =COUNTIF(M11, "<30") -> 0 | W11: =COUNTIF(N11, "<30") -> 1 | X11: =COUNTIF(O11, "<30") -> 1 | Y11: =COUNTIF(Q11, "<30") -> 1 | Z11: =COUNTIF(R11, "<30") -> 0 | AA11: =COUNTIF(S11, "<30") -> 0 | AB11: =COUNTIF(U11:AA11, ">0") -> 3
A12: =A11+1 -> 9 | B12: B9871SEI | C12: PT. TRANSMIGASINDO | F12: 46259 | G12: 46259 | H12: 46259 | I12: 46259 | L12: =IF(OR($AD$1="",D12=""),"",D12-$AD$1) | M12: =IF(OR($AD$1="",E12=""),"",E12-$AD$1) | N12: =IF(OR($AD$1="",F12=""),"",F12-$AD$1) -> -38 | O12: =IF(OR($AD$1="",G12=""),"",G12-$AD$1) -> -38 | P12: =IF(OR($AD$1="",H12=""),"",H12-$AD$1) -> -38 | Q12: =IF(OR($AD$1="",I12=""),"",I12-$AD$1) -> -38 | R12: =IF(OR($AD$1="",J12=""),"",J12-$AD$1) | S12: =IF(OR($AD$1="",K12=""),"",K12-$AD$1) | U12: =COUNTIF(L12, "<30") -> 0 | V12: =COUNTIF(M12, "<30") -> 0 | W12: =COUNTIF(N12, "<30") -> 1 | X12: =COUNTIF(O12, "<30") -> 1 | Y12: =COUNTIF(Q12, "<30") -> 1 | Z12: =COUNTIF(R12, "<30") -> 0 | AA12: =COUNTIF(S12, "<30") -> 0 | AB12: =COUNTIF(U12:AA12, ">0") -> 3
A13: =A12+1 -> 10 | B13: B9866SEI | C13: PT. TRANSMIGASINDO | F13: 46259 | G13: 46259 | H13: 46259 | I13: 46259 | L13: =IF(OR($AD$1="",D13=""),"",D13-$AD$1) | M13: =IF(OR($AD$1="",E13=""),"",E13-$AD$1) | N13: =IF(OR($AD$1="",F13=""),"",F13-$AD$1) -> -38 | O13: =IF(OR($AD$1="",G13=""),"",G13-$AD$1) -> -38 | P13: =IF(OR($AD$1="",H13=""),"",H13-$AD$1) -> -38 | Q13: =IF(OR($AD$1="",I13=""),"",I13-$AD$1) -> -38 | R13: =IF(OR($AD$1="",J13=""),"",J13-$AD$1) | S13: =IF(OR($AD$1="",K13=""),"",K13-$AD$1) | U13: =COUNTIF(L13, "<30") -> 0 | V13: =COUNTIF(M13, "<30") -> 0 | W13: =COUNTIF(N13, "<30") -> 1 | X13: =COUNTIF(O13, "<30") -> 1 | Y13: =COUNTIF(Q13, "<30") -> 1 | Z13: =COUNTIF(R13, "<30") -> 0 | AA13: =COUNTIF(S13, "<30") -> 0 | AB13: =COUNTIF(U13:AA13, ">0") -> 3
A14: =A13+1 -> 11 | B14: B9874SEI | C14: PT. TRANSMIGASINDO | F14: 46259 | G14: 46259 | H14: 46259 | I14: 46259 | L14: =IF(OR($AD$1="",D14=""),"",D14-$AD$1) | M14: =IF(OR($AD$1="",E14=""),"",E14-$AD$1) | N14: =IF(OR($AD$1="",F14=""),"",F14-$AD$1) -> -38 | O14: =IF(OR($AD$1="",G14=""),"",G14-$AD$1) -> -38 | P14: =IF(OR($AD$1="",H14=""),"",H14-$AD$1) -> -38 | Q14: =IF(OR($AD$1="",I14=""),"",I14-$AD$1) -> -38 | R14: =IF(OR($AD$1="",J14=""),"",J14-$AD$1) | S14: =IF(OR($AD$1="",K14=""),"",K14-$AD$1) | U14: =COUNTIF(L14, "<30") -> 0 | V14: =COUNTIF(M14, "<30") -> 0 | W14: =COUNTIF(N14, "<30") -> 1 | X14: =COUNTIF(O14, "<30") -> 1 | Y14: =COUNTIF(Q14, "<30") -> 1 | Z14: =COUNTIF(R14, "<30") -> 0 | AA14: =COUNTIF(S14, "<30") -> 0 | AB14: =COUNTIF(U14:AA14, ">0") -> 3
A15: =A14+1 -> 12 | B15: B9906SEI | C15: PT. TRANSMIGASINDO | F15: 46259 | G15: 46259 | H15: 46259 | I15: 46259 | L15: =IF(OR($AD$1="",D15=""),"",D15-$AD$1) | M15: =IF(OR($AD$1="",E15=""),"",E15-$AD$1) | N15: =IF(OR($AD$1="",F15=""),"",F15-$AD$1) -> -38 | O15: =IF(OR($AD$1="",G15=""),"",G15-$AD$1) -> -38 | P15: =IF(OR($AD$1="",H15=""),"",H15-$AD$1) -> -38 | Q15: =IF(OR($AD$1="",I15=""),"",I15-$AD$1) -> -38 | R15: =IF(OR($AD$1="",J15=""),"",J15-$AD$1) | S15: =IF(OR($AD$1="",K15=""),"",K15-$AD$1) | U15: =COUNTIF(L15, "<30") -> 0 | V15: =COUNTIF(M15, "<30") -> 0 | W15: =COUNTIF(N15, "<30") -> 1 | X15: =COUNTIF(O15, "<30") -> 1 | Y15: =COUNTIF(Q15, "<30") -> 1 | Z15: =COUNTIF(R15, "<30") -> 0 | AA15: =COUNTIF(S15, "<30") -> 0 | AB15: =COUNTIF(U15:AA15, ">0") -> 3
A16: =A15+1 -> 13 | B16: B9907SEI | C16: PT. TRANSMIGASINDO | F16: 46259 | G16: 46259 | H16: 46259 | I16: 46259 | L16: =IF(OR($AD$1="",D16=""),"",D16-$AD$1) | M16: =IF(OR($AD$1="",E16=""),"",E16-$AD$1) | N16: =IF(OR($AD$1="",F16=""),"",F16-$AD$1) -> -38 | O16: =IF(OR($AD$1="",G16=""),"",G16-$AD$1) -> -38 | P16: =IF(OR($AD$1="",H16=""),"",H16-$AD$1) -> -38 | Q16: =IF(OR($AD$1="",I16=""),"",I16-$AD$1) -> -38 | R16: =IF(OR($AD$1="",J16=""),"",J16-$AD$1) | S16: =IF(OR($AD$1="",K16=""),"",K16-$AD$1) | U16: =COUNTIF(L16, "<30") -> 0 | V16: =COUNTIF(M16, "<30") -> 0 | W16: =COUNTIF(N16, "<30") -> 1 | X16: =COUNTIF(O16, "<30") -> 1 | Y16: =COUNTIF(Q16, "<30") -> 1 | Z16: =COUNTIF(R16, "<30") -> 0 | AA16: =COUNTIF(S16, "<30") -> 0 | AB16: =COUNTIF(U16:AA16, ">0") -> 3
A17: =A16+1 -> 14 | B17: B9908SEI | C17: PT. TRANSMIGASINDO | F17: 46259 | G17: 46259 | H17: 46259 | I17: 46259 | L17: =IF(OR($AD$1="",D17=""),"",D17-$AD$1) | M17: =IF(OR($AD$1="",E17=""),"",E17-$AD$1) | N17: =IF(OR($AD$1="",F17=""),"",F17-$AD$1) -> -38 | O17: =IF(OR($AD$1="",G17=""),"",G17-$AD$1) -> -38 | P17: =IF(OR($AD$1="",H17=""),"",H17-$AD$1) -> -38 | Q17: =IF(OR($AD$1="",I17=""),"",I17-$AD$1) -> -38 | R17: =IF(OR($AD$1="",J17=""),"",J17-$AD$1) | S17: =IF(OR($AD$1="",K17=""),"",K17-$AD$1) | U17: =COUNTIF(L17, "<30") -> 0 | V17: =COUNTIF(M17, "<30") -> 0 | W17: =COUNTIF(N17, "<30") -> 1 | X17: =COUNTIF(O17, "<30") -> 1 | Y17: =COUNTIF(Q17, "<30") -> 1 | Z17: =COUNTIF(R17, "<30") -> 0 | AA17: =COUNTIF(S17, "<30") -> 0 | AB17: =COUNTIF(U17:AA17, ">0") -> 3
A18: =A17+1 -> 15 | B18: B9683SFU | C18: PT. PPN | H18: 46081 | I18: 46081 | J18: 46081 | K18: 46081 | N18: =IF(OR($AD$1="",F18=""),"",F18-$AD$1) | O18: =IF(OR($AD$1="",G18=""),"",G18-$AD$1) | P18: =IF(OR($AD$1="",H18=""),"",H18-$AD$1) -> -216 | Q18: =IF(OR($AD$1="",I18=""),"",I18-$AD$1) -> -216 | R18: =IF(OR($AD$1="",J18=""),"",J18-$AD$1) -> -216 | S18: =IF(OR($AD$1="",K18=""),"",K18-$AD$1) -> -216 | U18: =COUNTIF(L18, "<30") -> 0 | V18: =COUNTIF(M18, "<30") -> 0 | W18: =COUNTIF(N18, "<30") -> 0 | X18: =COUNTIF(O18, "<30") -> 0 | Y18: =COUNTIF(Q18, "<30") -> 1 | Z18: =COUNTIF(R18, "<30") -> 1 | AA18: =COUNTIF(S18, "<30") -> 1 | AB18: =COUNTIF(U18:AA18, ">0") -> 3
A19: =A18+1 -> 16 | B19: R9029B | C19: PT. SERAYU MITRA JAYA | F19: 46292 | H19: 46292 | I19: 46292 | J19: 46292 | M19: =IF(OR($AD$1="",E19=""),"",E19-$AD$1) | N19: =IF(OR($AD$1="",F19=""),"",F19-$AD$1) -> -5 | O19: =IF(OR($AD$1="",G19=""),"",G19-$AD$1) | P19: =IF(OR($AD$1="",H19=""),"",H19-$AD$1) -> -5 | Q19: =IF(OR($AD$1="",I19=""),"",I19-$AD$1) -> -5 | R19: =IF(OR($AD$1="",J19=""),"",J19-$AD$1) -> -5 | S19: =IF(OR($AD$1="",K19=""),"",K19-$AD$1) | U19: =COUNTIF(L19, "<30") -> 0 | V19: =COUNTIF(M19, "<30") -> 0 | W19: =COUNTIF(N19, "<30") -> 1 | X19: =COUNTIF(O19, "<30") -> 0 | Y19: =COUNTIF(Q19, "<30") -> 1 | Z19: =COUNTIF(R19, "<30") -> 1 | AA19: =COUNTIF(S19, "<30") -> 0 | AB19: =COUNTIF(U19:AA19, ">0") -> 3
A20: =A19+1 -> 17 | B20: R9693B | C20: PT. SERAYU MITRA JAYA | F20: 46292 | H20: 46292 | I20: 46292 | K20: 46292 | L20: =IF(OR($AD$1="",D20=""),"",D20-$AD$1) | M20: =IF(OR($AD$1="",E20=""),"",E20-$AD$1) | N20: =IF(OR($AD$1="",F20=""),"",F20-$AD$1) -> -5 | O20: =IF(OR($AD$1="",G20=""),"",G20-$AD$1) | P20: =IF(OR($AD$1="",H20=""),"",H20-$AD$1) -> -5 | Q20: =IF(OR($AD$1="",I20=""),"",I20-$AD$1) -> -5 | R20: =IF(OR($AD$1="",J20=""),"",J20-$AD$1) | S20: =IF(OR($AD$1="",K20=""),"",K20-$AD$1) -> -5 | U20: =COUNTIF(L20, "<30") -> 0 | V20: =COUNTIF(M20, "<30") -> 0 | W20: =COUNTIF(N20, "<30") -> 1 | X20: =COUNTIF(O20, "<30") -> 0 | Y20: =COUNTIF(Q20, "<30") -> 1 | Z20: =COUNTIF(R20, "<30") -> 0 | AA20: =COUNTIF(S20, "<30") -> 1 | AB20: =COUNTIF(U20:AA20, ">0") -> 3
B21: R9694B | C21: PT. SERAYU MITRA JAYA
A22: =A20+1 -> 18 | B22: R8336B | C22: PT. SERAYU MITRA JAYA | G22: 46111 | K22: 46111 | L22: =IF(OR($AD$1="",D22=""),"",D22-$AD$1) | M22: =IF(OR($AD$1="",E22=""),"",E22-$AD$1) | N22: =IF(OR($AD$1="",F22=""),"",F22-$AD$1) | O22: =IF(OR($AD$1="",G22=""),"",G22-$AD$1) -> -186 | P22: =IF(OR($AD$1="",H22=""),"",H22-$AD$1) | Q22: =IF(OR($AD$1="",I22=""),"",I22-$AD$1) | R22: =IF(OR($AD$1="",J22=""),"",J22-$AD$1) | S22: =IF(OR($AD$1="",K22=""),"",K22-$AD$1) -> -186 | U22: =COUNTIF(L22, "<30") -> 0 | V22: =COUNTIF(M22, "<30") -> 0 | W22: =COUNTIF(N22, "<30") -> 0 | X22: =COUNTIF(O22, "<30") -> 1 | Y22: =COUNTIF(Q22, "<30") -> 0 | Z22: =COUNTIF(R22, "<30") -> 0 | AA22: =COUNTIF(S22, "<30") -> 1 | AB22: =COUNTIF(U22:AA22, ">0") -> 2
A23: =A22+1 -> 19 | B23: R8084K | C23: PT. SERAYU MITRA JAYA | F23: 46292 | G23: 46292 | H23: 46292 | I23: 46292 | L23: =IF(OR($AD$1="",D23=""),"",D23-$AD$1) | M23: =IF(OR($AD$1="",E23=""),"",E23-$AD$1) | N23: =IF(OR($AD$1="",F23=""),"",F23-$AD$1) -> -5 | O23: =IF(OR($AD$1="",G23=""),"",G23-$AD$1) -> -5 | P23: =IF(OR($AD$1="",H23=""),"",H23-$AD$1) -> -5 | Q23: =IF(OR($AD$1="",I23=""),"",I23-$AD$1) -> -5 | R23: =IF(OR($AD$1="",J23=""),"",J23-$AD$1) | S23: =IF(OR($AD$1="",K23=""),"",K23-$AD$1) | U23: =COUNTIF(L23, "<30") -> 0 | V23: =COUNTIF(M23, "<30") -> 0 | W23: =COUNTIF(N23, "<30") -> 1 | X23: =COUNTIF(O23, "<30") -> 1 | Y23: =COUNTIF(Q23, "<30") -> 1 | Z23: =COUNTIF(R23, "<30") -> 0 | AA23: =COUNTIF(S23, "<30") -> 0 | AB23: =COUNTIF(U23:AA23, ">0") -> 3
A24: =A23+1 -> 20 | B24: R9694B | C24: PT. SERAYU MITRA JAYA | F24: 46292 | H24: 46292 | I24: 46292 | K24: 46292 | L24: =IF(OR($AD$1="",D24=""),"",D24-$AD$1) | M24: =IF(OR($AD$1="",E24=""),"",E24-$AD$1) | N24: =IF(OR($AD$1="",F24=""),"",F24-$AD$1) -> -5 | O24: =IF(OR($AD$1="",G24=""),"",G24-$AD$1) | P24: =IF(OR($AD$1="",H24=""),"",H24-$AD$1) -> -5 | Q24: =IF(OR($AD$1="",I24=""),"",I24-$AD$1) -> -5 | R24: =IF(OR($AD$1="",J24=""),"",J24-$AD$1) | S24: =IF(OR($AD$1="",K24=""),"",K24-$AD$1) -> -5 | U24: =COUNTIF(L24, "<30") -> 0 | V24: =COUNTIF(M24, "<30") -> 0 | W24: =COUNTIF(N24, "<30") -> 1 | X24: =COUNTIF(O24, "<30") -> 0 | Y24: =COUNTIF(Q24, "<30") -> 1 | Z24: =COUNTIF(R24, "<30") -> 0 | AA24: =COUNTIF(S24, "<30") -> 1 | AB24: =COUNTIF(U24:AA24, ">0") -> 3
L25: =SUM(L24:M24) -> 0
B27: BOCOR
B28: BBM CILACAP
B29: APAR PENGADAAN BARU DARI TRANSPORTIR
B30: ALIH SUPPLY LUAR KOTA

Sheet REKAP APAR OTOMATIC
D1: Tanggal Service Exp Apar | I1: Tanggal Service Exp Apar Cadangan | N1: KETERANGAN APAR HARI | T1: UNIT EXP APAR | AA1: =TODAY() -> 46297
A2: NO | B2: NOPOL | C2: TRANSPORTIR | D2: CO2 PERTAMA | E2: CO2 KEDUA | F2: DCP PRESSURE | G2: FOAM | H2: DCP CATRIDGE | I2: CO2 Pertama | J2: CO2 Kedua | K2: DCP | L2: Foam | M2: Catride | N2: CO2 PERTAMA | O2: CO2 KEDUA | P2: DCP PRESSURE | Q2: FOAM | R2: DCP CATRIDGE | T2: CO2 Pertama | U2: CO2 Kedua | V2: DCP | W2: Foam | X2: Catride | Y2: Jumlah
A4: 1 | B4: AD8603OH | C4: PT. Karyamas | D4: =IFERROR( IF(VLOOKUP(B4,'SUMBER REKAP APAR'!F:O,2,FALSE)="", VLOOKUP(B4,'REKAP APAR FT MAOS'!B:J,3,FALSE), VLOOKUP(B4,'SUMBER REKAP APAR'!F:O,2,FALSE) ), VLOOKUP(B4,'REKAP APAR FT MAOS'!B:J,3,FALSE) ) -> 0 | E4: =IFERROR( IF(VLOOKUP(B4,'SUMBER REKAP APAR'!F:O,3,FALSE)="", VLOOKUP(B4,'REKAP APAR FT MAOS'!B:J,4,FALSE), VLOOKUP(B4,'SUMBER REKAP APAR'!F:O,3,FALSE) ), VLOOKUP(B4,'REKAP APAR FT MAOS'!B:J,4,FALSE) ) -> 0 | F4: =IFERROR( IF(VLOOKUP(B4,'SUMBER REKAP APAR'!F:O,4,FALSE)="", VLOOKUP(B4,'REKAP APAR FT MAOS'!B:J,5,FALSE), VLOOKUP(B4,'SUMBER REKAP APAR'!F:O,4,FALSE) ), VLOOKUP(B4,'REKAP APAR FT MAOS'!B:J,5,FALSE) ) -> 46254 | G4: =IFERROR( IF(VLOOKUP(B4,'SUMBER REKAP APAR'!F:O,5,FALSE)="", VLOOKUP(B4,'REKAP APAR FT MAOS'!B:J,6,FALSE), VLOOKUP(B4,'SUMBER REKAP APAR'!F:O,5,FALSE) ), VLOOKUP(B4,'REKAP APAR FT MAOS'!B:J,6,FALSE) ) -> 46254 | H4: =IFERROR( IF(VLOOKUP(B4,'SUMBER REKAP APAR'!F:O,6,FALSE)="", VLOOKUP(B4,'REKAP APAR FT MAOS'!B:J,7,FALSE), VLOOKUP(B4,'SUMBER REKAP APAR'!F:O,6,FALSE) ), VLOOKUP(B4,'REKAP APAR FT MAOS'!B:J,7,FALSE) ) -> 0 | I4: =IFERROR( IF(VLOOKUP(B4,'SUMBER REKAP APAR'!F:O,7,FALSE)="", VLOOKUP(B4,'REKAP APAR FT MAOS'!B:J,8,FALSE), VLOOKUP(B4,'SUMBER REKAP APAR'!F:O,7,FALSE) ), VLOOKUP(B4,'REKAP APAR FT MAOS'!B:J,8,FALSE) ) -> 46254 | J4: =IFERROR( IF(VLOOKUP(B4,'SUMBER REKAP APAR'!F:O,8,FALSE)="", VLOOKUP(B4,'REKAP APAR FT MAOS'!B:J,9,FALSE), VLOOKUP(B4,'SUMBER REKAP APAR'!F:O,8,FALSE) ), VLOOKUP(B4,'REKAP APAR FT MAOS'!B:J,9,FALSE) ) -> 46352 | K4: =IFERROR( IF(VLOOKUP(B4,'SUMBER REKAP APAR'!F:O,9,FALSE)="", VLOOKUP(B4,'REKAP APAR FT MAOS'!B:J,10,FALSE), VLOOKUP(B4,'SUMBER REKAP APAR'!F:O,9,FALSE) ), VLOOKUP(B4,'REKAP APAR FT MAOS'!B:J,10,FALSE) ) -> #REF! | L4: =IFERROR( IF(VLOOKUP(B4,'SUMBER REKAP APAR'!F:O,10,FALSE)="", VLOOKUP(B4,'REKAP APAR FT MAOS'!B:J,11,FALSE), VLOOKUP(B4,'SUMBER REKAP APAR'!F:O,10,FALSE) ), VLOOKUP(B4,'REKAP APAR FT MAOS'!B:J,11,FALSE) ) -> #REF! | M4: =IFERROR( IF(VLOOKUP(B4,'SUMBER REKAP APAR'!F:Q,11,FALSE)="", VLOOKUP(B4,'REKAP APAR FT MAOS'!B:J,12,FALSE), VLOOKUP(B4,'SUMBER REKAP APAR'!F:Q,11,FALSE) ), VLOOKUP(B4,'REKAP APAR FT MAOS'!B:J,12,FALSE) ) -> #REF! | N4: =IF(OR($AA$1="",D4=""),"",D4-$AA$1) -> -46297 | O4: =IF(OR($AA$1="",E4=""),"",E4-$AA$1) -> -46297 | P4: =IF(OR($AA$1="",F4=""),"",F4-$AA$1) -> -43 | Q4: =IF(OR($AA$1="",G4=""),"",G4-$AA$1) -> -43 | R4: =IF(OR($AA$1="",H4=""),"",H4-$AA$1) -> -46297 | T4: =COUNTIF(N4, "<30") -> 1 | U4: =COUNTIF(O4, "<30") -> 1 | V4: =COUNTIF(P4, "<30") -> 1 | W4: =COUNTIF(Q4, "<30") -> 1 | X4: =COUNTIF(R4, "<30") -> 1 | Y4: =COUNTIF(T4:X4, ">0") -> 5
A5: 2 | B5: AD8618OH | C5: PT. Karyamas | D5: =IFERROR( IF(VLOOKUP(B5,'SUMBER REKAP APAR'!F:O,2,FALSE)="", VLOOKUP(B5,'REKAP APAR FT MAOS'!B:J,3,FALSE), VLOOKUP(B5,'SUMBER REKAP APAR'!F:O,2,FALSE) ), VLOOKUP(B5,'REKAP APAR FT MAOS'!B:J,3,FALSE) ) -> 0 | E5: =IFERROR( IF(VLOOKUP(B5,'SUMBER REKAP APAR'!F:O,3,FALSE)="", VLOOKUP(B5,'REKAP APAR FT MAOS'!B:J,4,FALSE), VLOOKUP(B5,'SUMBER REKAP APAR'!F:O,3,FALSE) ), VLOOKUP(B5,'REKAP APAR FT MAOS'!B:J,4,FALSE) ) -> 0 | F5: =IFERROR( IF(VLOOKUP(B5,'SUMBER REKAP APAR'!F:O,4,FALSE)="", VLOOKUP(B5,'REKAP APAR FT MAOS'!B:J,5,FALSE), VLOOKUP(B5,'SUMBER REKAP APAR'!F:O,4,FALSE) ), VLOOKUP(B5,'REKAP APAR FT MAOS'!B:J,5,FALSE) ) -> 46352 | G5: =IFERROR( IF(VLOOKUP(B5,'SUMBER REKAP APAR'!F:O,5,FALSE)="", VLOOKUP(B5,'REKAP APAR FT MAOS'!B:J,6,FALSE), VLOOKUP(B5,'SUMBER REKAP APAR'!F:O,5,FALSE) ), VLOOKUP(B5,'REKAP APAR FT MAOS'!B:J,6,FALSE) ) -> 46418 | H5: =IFERROR( IF(VLOOKUP(B5,'SUMBER REKAP APAR'!F:O,6,FALSE)="", VLOOKUP(B5,'REKAP APAR FT MAOS'!B:J,7,FALSE), VLOOKUP(B5,'SUMBER REKAP APAR'!F:O,6,FALSE) ), VLOOKUP(B5,'REKAP APAR FT MAOS'!B:J,7,FALSE) ) -> 0 | I5: =IFERROR( IF(VLOOKUP(B5,'SUMBER REKAP APAR'!F:O,7,FALSE)="", VLOOKUP(B5,'REKAP APAR FT MAOS'!B:J,8,FALSE), VLOOKUP(B5,'SUMBER REKAP APAR'!F:O,7,FALSE) ), VLOOKUP(B5,'REKAP APAR FT MAOS'!B:J,8,FALSE) ) -> 46418 | J5: =IFERROR( IF(VLOOKUP(B5,'SUMBER REKAP APAR'!F:O,8,FALSE)="", VLOOKUP(B5,'REKAP APAR FT MAOS'!B:J,9,FALSE), VLOOKUP(B5,'SUMBER REKAP APAR'!F:O,8,FALSE) ), VLOOKUP(B5,'REKAP APAR FT MAOS'!B:J,9,FALSE) ) -> 46418 | K5: =IFERROR( IF(VLOOKUP(B5,'SUMBER REKAP APAR'!F:O,9,FALSE)="", VLOOKUP(B5,'REKAP APAR FT MAOS'!B:J,10,FALSE), VLOOKUP(B5,'SUMBER REKAP APAR'!F:O,9,FALSE) ), VLOOKUP(B5,'REKAP APAR FT MAOS'!B:J,10,FALSE) ) -> #REF! | L5: =IFERROR( IF(VLOOKUP(B5,'SUMBER REKAP APAR'!F:O,10,FALSE)="", VLOOKUP(B5,'REKAP APAR FT MAOS'!B:J,11,FALSE), VLOOKUP(B5,'SUMBER REKAP APAR'!F:O,10,FALSE) ), VLOOKUP(B5,'REKAP APAR FT MAOS'!B:J,11,FALSE) ) -> #REF! | M5: =IFERROR( IF(VLOOKUP(B5,'SUMBER REKAP APAR'!F:Q,11,FALSE)="", VLOOKUP(B5,'REKAP APAR FT MAOS'!B:J,12,FALSE), VLOOKUP(B5,'SUMBER REKAP APAR'!F:Q,11,FALSE) ), VLOOKUP(B5,'REKAP APAR FT MAOS'!B:J,12,FALSE) ) -> #REF! | N5: =IF(OR($AA$1="",D5=""),"",D5-$AA$1) -> -46297 | O5: =IF(OR($AA$1="",E5=""),"",E5-$AA$1) -> -46297 | P5: =IF(OR($AA$1="",F5=""),"",F5-$AA$1) -> 55 | Q5: =IF(OR($AA$1="",G5=""),"",G5-$AA$1) -> 121 | R5: =IF(OR($AA$1="",H5=""),"",H5-$AA$1) -> -46297 | T5: =COUNTIF(N5, "<30") -> 1 | U5: =COUNTIF(O5, "<30") -> 1 | V5: =COUNTIF(P5, "<30") -> 0 | W5: =COUNTIF(Q5, "<30") -> 0 | X5: =COUNTIF(R5, "<30") -> 1 | Y5: =COUNTIF(T5:X5, ">0") -> 3
A6: 3 | B6: B9800SFU | C6: PT. PPN | D6: =IFERROR( IF(VLOOKUP(B6,'SUMBER REKAP APAR'!F:O,2,FALSE)="", VLOOKUP(B6,'REKAP APAR FT MAOS'!B:J,3,FALSE), VLOOKUP(B6,'SUMBER REKAP APAR'!F:O,2,FALSE) ), VLOOKUP(B6,'REKAP APAR FT MAOS'!B:J,3,FALSE) ) -> #N/A | E6: =IFERROR( IF(VLOOKUP(B6,'SUMBER REKAP APAR'!F:O,3,FALSE)="", VLOOKUP(B6,'REKAP APAR FT MAOS'!B:J,4,FALSE), VLOOKUP(B6,'SUMBER REKAP APAR'!F:O,3,FALSE) ), VLOOKUP(B6,'REKAP APAR FT MAOS'!B:J,4,FALSE) ) -> #N/A | F6: =IFERROR( IF(VLOOKUP(B6,'SUMBER REKAP APAR'!F:O,4,FALSE)="", VLOOKUP(B6,'REKAP APAR FT MAOS'!B:J,5,FALSE), VLOOKUP(B6,'SUMBER REKAP APAR'!F:O,4,FALSE) ), VLOOKUP(B6,'REKAP APAR FT MAOS'!B:J,5,FALSE) ) -> #N/A | G6: =IFERROR( IF(VLOOKUP(B6,'SUMBER REKAP APAR'!F:O,5,FALSE)="", VLOOKUP(B6,'REKAP APAR FT MAOS'!B:J,6,FALSE), VLOOKUP(B6,'SUMBER REKAP APAR'!F:O,5,FALSE) ), VLOOKUP(B6,'REKAP APAR FT MAOS'!B:J,6,FALSE) ) -> #N/A | H6: =IFERROR( IF(VLOOKUP(B6,'SUMBER REKAP APAR'!F:O,6,FALSE)="", VLOOKUP(B6,'REKAP APAR FT MAOS'!B:J,7,FALSE), VLOOKUP(B6,'SUMBER REKAP APAR'!F:O,6,FALSE) ), VLOOKUP(B6,'REKAP APAR FT MAOS'!B:J,7,FALSE) ) -> #N/A | I6: =IFERROR( IF(VLOOKUP(B6,'SUMBER REKAP APAR'!F:O,7,FALSE)="", VLOOKUP(B6,'REKAP APAR FT MAOS'!B:J,8,FALSE), VLOOKUP(B6,'SUMBER REKAP APAR'!F:O,7,FALSE) ), VLOOKUP(B6,'REKAP APAR FT MAOS'!B:J,8,FALSE) ) -> #N/A | J6: =IFERROR( IF(VLOOKUP(B6,'SUMBER REKAP APAR'!F:O,8,FALSE)="", VLOOKUP(B6,'REKAP APAR FT MAOS'!B:J,9,FALSE), VLOOKUP(B6,'SUMBER REKAP APAR'!F:O,8,FALSE) ), VLOOKUP(B6,'REKAP APAR FT MAOS'!B:J,9,FALSE) ) -> #N/A | K6: =IFERROR( IF(VLOOKUP(B6,'SUMBER REKAP APAR'!F:O,9,FALSE)="", VLOOKUP(B6,'REKAP APAR FT MAOS'!B:J,10,FALSE), VLOOKUP(B6,'SUMBER REKAP APAR'!F:O,9,FALSE) ), VLOOKUP(B6,'REKAP APAR FT MAOS'!B:J,10,FALSE) ) -> #N/A | L6: =IFERROR( IF(VLOOKUP(B6,'SUMBER REKAP APAR'!F:O,10,FALSE)="", VLOOKUP(B6,'REKAP APAR FT MAOS'!B:J,11,FALSE), VLOOKUP(B6,'SUMBER REKAP APAR'!F:O,10,FALSE) ), VLOOKUP(B6,'REKAP APAR FT MAOS'!B:J,11,FALSE) ) -> #N/A | M6: =IFERROR( IF(VLOOKUP(B6,'SUMBER REKAP APAR'!F:Q,11,FALSE)="", VLOOKUP(B6,'REKAP APAR FT MAOS'!B:J,12,FALSE), VLOOKUP(B6,'SUMBER REKAP APAR'!F:Q,11,FALSE) ), VLOOKUP(B6,'REKAP APAR FT MAOS'!B:J,12,FALSE) ) -> #N/A | N6: =IF(OR($AA$1="",D6=""),"",D6-$AA$1) -> #N/A | O6: =IF(OR($AA$1="",E6=""),"",E6-$AA$1) -> #N/A | P6: =IF(OR($AA$1="",F6=""),"",F6-$AA$1) -> #N/A | Q6: =IF(OR($AA$1="",G6=""),"",G6-$AA$1) -> #N/A | R6: =IF(OR($AA$1="",H6=""),"",H6-$AA$1) -> #N/A | T6: =COUNTIF(N6, "<30") -> 0 | U6: =COUNTIF(O6, "<30") -> 0 | V6: =COUNTIF(P6, "<30") -> 0 | W6: =COUNTIF(Q6, "<30") -> 0 | X6: =COUNTIF(R6, "<30") -> 0 | Y6: =COUNTIF(T6:X6, ">0") -> 0
A7: 4 | B7: B9805SFU | C7: PT. PPN | D7: =IFERROR( IF(VLOOKUP(B7,'SUMBER REKAP APAR'!F:O,2,FALSE)="", VLOOKUP(B7,'REKAP APAR FT MAOS'!B:J,3,FALSE), VLOOKUP(B7,'SUMBER REKAP APAR'!F:O,2,FALSE) ), VLOOKUP(B7,'REKAP APAR FT MAOS'!B:J,3,FALSE) ) -> #N/A | E7: =IFERROR( IF(VLOOKUP(B7,'SUMBER REKAP APAR'!F:O,3,FALSE)="", VLOOKUP(B7,'REKAP APAR FT MAOS'!B:J,4,FALSE), VLOOKUP(B7,'SUMBER REKAP APAR'!F:O,3,FALSE) ), VLOOKUP(B7,'REKAP APAR FT MAOS'!B:J,4,FALSE) ) -> #N/A | F7: =IFERROR( IF(VLOOKUP(B7,'SUMBER REKAP APAR'!F:O,4,FALSE)="", VLOOKUP(B7,'REKAP APAR FT MAOS'!B:J,5,FALSE), VLOOKUP(B7,'SUMBER REKAP APAR'!F:O,4,FALSE) ), VLOOKUP(B7,'REKAP APAR FT MAOS'!B:J,5,FALSE) ) -> 46111 | G7: =IFERROR( IF(VLOOKUP(B7,'SUMBER REKAP APAR'!F:O,5,FALSE)="", VLOOKUP(B7,'REKAP APAR FT MAOS'!B:J,6,FALSE), VLOOKUP(B7,'SUMBER REKAP APAR'!F:O,5,FALSE) ), VLOOKUP(B7,'REKAP APAR FT MAOS'!B:J,6,FALSE) ) -> 46111 | H7: =IFERROR( IF(VLOOKUP(B7,'SUMBER REKAP APAR'!F:O,6,FALSE)="", VLOOKUP(B7,'REKAP APAR FT MAOS'!B:J,7,FALSE), VLOOKUP(B7,'SUMBER REKAP APAR'!F:O,6,FALSE) ), VLOOKUP(B7,'REKAP APAR FT MAOS'!B:J,7,FALSE) ) -> #N/A | I7: =IFERROR( IF(VLOOKUP(B7,'SUMBER REKAP APAR'!F:O,7,FALSE)="", VLOOKUP(B7,'REKAP APAR FT MAOS'!B:J,8,FALSE), VLOOKUP(B7,'SUMBER REKAP APAR'!F:O,7,FALSE) ), VLOOKUP(B7,'REKAP APAR FT MAOS'!B:J,8,FALSE) ) -> #N/A | J7: =IFERROR( IF(VLOOKUP(B7,'SUMBER REKAP APAR'!F:O,8,FALSE)="", VLOOKUP(B7,'REKAP APAR FT MAOS'!B:J,9,FALSE), VLOOKUP(B7,'SUMBER REKAP APAR'!F:O,8,FALSE) ), VLOOKUP(B7,'REKAP APAR FT MAOS'!B:J,9,FALSE) ) -> #N/A | K7: =IFERROR( IF(VLOOKUP(B7,'SUMBER REKAP APAR'!F:O,9,FALSE)="", VLOOKUP(B7,'REKAP APAR FT MAOS'!B:J,10,FALSE), VLOOKUP(B7,'SUMBER REKAP APAR'!F:O,9,FALSE) ), VLOOKUP(B7,'REKAP APAR FT MAOS'!B:J,10,FALSE) ) -> #N/A | L7: =IFERROR( IF(VLOOKUP(B7,'SUMBER REKAP APAR'!F:O,10,FALSE)="", VLOOKUP(B7,'REKAP APAR FT MAOS'!B:J,11,FALSE), VLOOKUP(B7,'SUMBER REKAP APAR'!F:O,10,FALSE) ), VLOOKUP(B7,'REKAP APAR FT MAOS'!B:J,11,FALSE) ) -> #N/A | M7: =IFERROR( IF(VLOOKUP(B7,'SUMBER REKAP APAR'!F:Q,11,FALSE)="", VLOOKUP(B7,'REKAP APAR FT MAOS'!B:J,12,FALSE), VLOOKUP(B7,'SUMBER REKAP APAR'!F:Q,11,FALSE) ), VLOOKUP(B7,'REKAP APAR FT MAOS'!B:J,12,FALSE) ) -> #N/A | N7: =IF(OR($AA$1="",D7=""),"",D7-$AA$1) -> #N/A | O7: =IF(OR($AA$1="",E7=""),"",E7-$AA$1) -> #N/A | P7: =IF(OR($AA$1="",F7=""),"",F7-$AA$1) -> -186 | Q7: =IF(OR($AA$1="",G7=""),"",G7-$AA$1) -> -186 | R7: =IF(OR($AA$1="",H7=""),"",H7-$AA$1) -> #N/A | T7: =COUNTIF(N7, "<30") -> 0 | U7: =COUNTIF(O7, "<30") -> 0 | V7: =COUNTIF(P7, "<30") -> 1 | W7: =COUNTIF(Q7, "<30") -> 1 | X7: =COUNTIF(R7, "<30") -> 0 | Y7: =COUNTIF(T7:X7, ">0") -> 2
A8: 5 | B8: B9077SEI | C8: PT. PPN | D8: =IFERROR( IF(VLOOKUP(B8,'SUMBER REKAP APAR'!F:O,2,FALSE)="", VLOOKUP(B8,'REKAP APAR FT MAOS'!B:J,3,FALSE), VLOOKUP(B8,'SUMBER REKAP APAR'!F:O,2,FALSE) ), VLOOKUP(B8,'REKAP APAR FT MAOS'!B:J,3,FALSE) ) -> 46053 | E8: =IFERROR( IF(VLOOKUP(B8,'SUMBER REKAP APAR'!F:O,3,FALSE)="", VLOOKUP(B8,'REKAP APAR FT MAOS'!B:J,4,FALSE), VLOOKUP(B8,'SUMBER REKAP APAR'!F:O,3,FALSE) ), VLOOKUP(B8,'REKAP APAR FT MAOS'!B:J,4,FALSE) ) -> 46053 | F8: =IFERROR( IF(VLOOKUP(B8,'SUMBER REKAP APAR'!F:O,4,FALSE)="", VLOOKUP(B8,'REKAP APAR FT MAOS'!B:J,5,FALSE), VLOOKUP(B8,'SUMBER REKAP APAR'!F:O,4,FALSE) ), VLOOKUP(B8,'REKAP APAR FT MAOS'!B:J,5,FALSE) ) -> 46053 | G8: =IFERROR( IF(VLOOKUP(B8,'SUMBER REKAP APAR'!F:O,5,FALSE)="", VLOOKUP(B8,'REKAP APAR FT MAOS'!B:J,6,FALSE), VLOOKUP(B8,'SUMBER REKAP APAR'!F:O,5,FALSE) ), VLOOKUP(B8,'REKAP APAR FT MAOS'!B:J,6,FALSE) ) -> 46053 | H8: =IFERROR( IF(VLOOKUP(B8,'SUMBER REKAP APAR'!F:O,6,FALSE)="", VLOOKUP(B8,'REKAP APAR FT MAOS'!B:J,7,FALSE), VLOOKUP(B8,'SUMBER REKAP APAR'!F:O,6,FALSE) ), VLOOKUP(B8,'REKAP APAR FT MAOS'!B:J,7,FALSE) ) -> 46292 | I8: =IFERROR( IF(VLOOKUP(B8,'SUMBER REKAP APAR'!F:O,7,FALSE)="", VLOOKUP(B8,'REKAP APAR FT MAOS'!B:J,8,FALSE), VLOOKUP(B8,'SUMBER REKAP APAR'!F:O,7,FALSE) ), VLOOKUP(B8,'REKAP APAR FT MAOS'!B:J,8,FALSE) ) -> 46292 | J8: =IFERROR( IF(VLOOKUP(B8,'SUMBER REKAP APAR'!F:O,8,FALSE)="", VLOOKUP(B8,'REKAP APAR FT MAOS'!B:J,9,FALSE), VLOOKUP(B8,'SUMBER REKAP APAR'!F:O,8,FALSE) ), VLOOKUP(B8,'REKAP APAR FT MAOS'!B:J,9,FALSE) ) -> 46292 | K8: =IFERROR( IF(VLOOKUP(B8,'SUMBER REKAP APAR'!F:O,9,FALSE)="", VLOOKUP(B8,'REKAP APAR FT MAOS'!B:J,10,FALSE), VLOOKUP(B8,'SUMBER REKAP APAR'!F:O,9,FALSE) ), VLOOKUP(B8,'REKAP APAR FT MAOS'!B:J,10,FALSE) ) -> #REF! | L8: =IFERROR( IF(VLOOKUP(B8,'SUMBER REKAP APAR'!F:O,10,FALSE)="", VLOOKUP(B8,'REKAP APAR FT MAOS'!B:J,11,FALSE), VLOOKUP(B8,'SUMBER REKAP APAR'!F:O,10,FALSE) ), VLOOKUP(B8,'REKAP APAR FT MAOS'!B:J,11,FALSE) ) -> #REF! | M8: =IFERROR( IF(VLOOKUP(B8,'SUMBER REKAP APAR'!F:Q,11,FALSE)="", VLOOKUP(B8,'REKAP APAR FT MAOS'!B:J,12,FALSE), VLOOKUP(B8,'SUMBER REKAP APAR'!F:Q,11,FALSE) ), VLOOKUP(B8,'REKAP APAR FT MAOS'!B:J,12,FALSE) ) -> #REF! | N8: =IF(OR($AA$1="",D8=""),"",D8-$AA$1) -> -244 | O8: =IF(OR($AA$1="",E8=""),"",E8-$AA$1) -> -244 | P8: =IF(OR($AA$1="",F8=""),"",F8-$AA$1) -> -244 | Q8: =IF(OR($AA$1="",G8=""),"",G8-$AA$1) -> -244 | R8: =IF(OR($AA$1="",H8=""),"",H8-$AA$1) -> -5 | T8: =COUNTIF(N8, "<30") -> 1 | U8: =COUNTIF(O8, "<30") -> 1 | V8: =COUNTIF(P8, "<30") -> 1 | W8: =COUNTIF(Q8, "<30") -> 1 | X8: =COUNTIF(R8, "<30") -> 1 | Y8: =COUNTIF(T8:X8, ">0") -> 5
A9: 6 | B9: B9106SEI | C9: PT. PPN | D9: =IFERROR( IF(VLOOKUP(B9,'SUMBER REKAP APAR'!F:O,2,FALSE)="", VLOOKUP(B9,'REKAP APAR FT MAOS'!B:J,3,FALSE), VLOOKUP(B9,'SUMBER REKAP APAR'!F:O,2,FALSE) ), VLOOKUP(B9,'REKAP APAR FT MAOS'!B:J,3,FALSE) ) -> 0 | E9: =IFERROR( IF(VLOOKUP(B9,'SUMBER REKAP APAR'!F:O,3,FALSE)="", VLOOKUP(B9,'REKAP APAR FT MAOS'!B:J,4,FALSE), VLOOKUP(B9,'SUMBER REKAP APAR'!F:O,3,FALSE) ), VLOOKUP(B9,'REKAP APAR FT MAOS'!B:J,4,FALSE) ) -> 0 | F9: =IFERROR( IF(VLOOKUP(B9,'SUMBER REKAP APAR'!F:O,4,FALSE)="", VLOOKUP(B9,'REKAP APAR FT MAOS'!B:J,5,FALSE), VLOOKUP(B9,'SUMBER REKAP APAR'!F:O,4,FALSE) ), VLOOKUP(B9,'REKAP APAR FT MAOS'!B:J,5,FALSE) ) -> 46111 | G9: =IFERROR( IF(VLOOKUP(B9,'SUMBER REKAP APAR'!F:O,5,FALSE)="", VLOOKUP(B9,'REKAP APAR FT MAOS'!B:J,6,FALSE), VLOOKUP(B9,'SUMBER REKAP APAR'!F:O,5,FALSE) ), VLOOKUP(B9,'REKAP APAR FT MAOS'!B:J,6,FALSE) ) -> 46111 | H9: =IFERROR( IF(VLOOKUP(B9,'SUMBER REKAP APAR'!F:O,6,FALSE)="", VLOOKUP(B9,'REKAP APAR FT MAOS'!B:J,7,FALSE), VLOOKUP(B9,'SUMBER REKAP APAR'!F:O,6,FALSE) ), VLOOKUP(B9,'REKAP APAR FT MAOS'!B:J,7,FALSE) ) -> 0 | I9: =IFERROR( IF(VLOOKUP(B9,'SUMBER REKAP APAR'!F:O,7,FALSE)="", VLOOKUP(B9,'REKAP APAR FT MAOS'!B:J,8,FALSE), VLOOKUP(B9,'SUMBER REKAP APAR'!F:O,7,FALSE) ), VLOOKUP(B9,'REKAP APAR FT MAOS'!B:J,8,FALSE) ) -> 46292 | J9: =IFERROR( IF(VLOOKUP(B9,'SUMBER REKAP APAR'!F:O,8,FALSE)="", VLOOKUP(B9,'REKAP APAR FT MAOS'!B:J,9,FALSE), VLOOKUP(B9,'SUMBER REKAP APAR'!F:O,8,FALSE) ), VLOOKUP(B9,'REKAP APAR FT MAOS'!B:J,9,FALSE) ) -> 46292 | K9: =IFERROR( IF(VLOOKUP(B9,'SUMBER REKAP APAR'!F:O,9,FALSE)="", VLOOKUP(B9,'REKAP APAR FT MAOS'!B:J,10,FALSE), VLOOKUP(B9,'SUMBER REKAP APAR'!F:O,9,FALSE) ), VLOOKUP(B9,'REKAP APAR FT MAOS'!B:J,10,FALSE) ) -> #REF! | L9: =IFERROR( IF(VLOOKUP(B9,'SUMBER REKAP APAR'!F:O,10,FALSE)="", VLOOKUP(B9,'REKAP APAR FT MAOS'!B:J,11,FALSE), VLOOKUP(B9,'SUMBER REKAP APAR'!F:O,10,FALSE) ), VLOOKUP(B9,'REKAP APAR FT MAOS'!B:J,11,FALSE) ) -> #REF! | M9: =IFERROR( IF(VLOOKUP(B9,'SUMBER REKAP APAR'!F:Q,11,FALSE)="", VLOOKUP(B9,'REKAP APAR FT MAOS'!B:J,12,FALSE), VLOOKUP(B9,'SUMBER REKAP APAR'!F:Q,11,FALSE) ), VLOOKUP(B9,'REKAP APAR FT MAOS'!B:J,12,FALSE) ) -> #REF! | N9: =IF(OR($AA$1="",D9=""),"",D9-$AA$1) -> -46297 | O9: =IF(OR($AA$1="",E9=""),"",E9-$AA$1) -> -46297 | P9: =IF(OR($AA$1="",F9=""),"",F9-$AA$1) -> -186 | Q9: =IF(OR($AA$1="",G9=""),"",G9-$AA$1) -> -186 | R9: =IF(OR($AA$1="",H9=""),"",H9-$AA$1) -> -46297 | T9: =COUNTIF(N9, "<30") -> 1 | U9: =COUNTIF(O9, "<30") -> 1 | V9: =COUNTIF(P9, "<30") -> 1 | W9: =COUNTIF(Q9, "<30") -> 1 | X9: =COUNTIF(R9, "<30") -> 1 | Y9: =COUNTIF(T9:X9, ">0") -> 5
